Workbook
Name lst_groups: '📚 Справочник'!$A$5:$A$24
Name lst_cats: '📚 Справочник'!$C$5:$C$24
Name lst_prio: '📚 Справочник'!$E$5:$E$7
Name lst_tstatus: '📚 Справочник'!$G$5:$G$8
Name lst_estatus: '📚 Справочник'!$I$5:$I$7
Name lst_years: '📚 Справочник'!$K$5:$K$9
Name lst_months: '📚 Справочник'!$L$5:$L$16
Name t_name: '✅ Задачи'!$B$5:$B$1004
Name t_group: '✅ Задачи'!$C$5:$C$1004
Name t_cat: '✅ Задачи'!$D$5:$D$1004
Name t_prio: '✅ Задачи'!$E$5:$E$1004
Name t_date: '✅ Задачи'!$F$5:$F$1004
Name t_status: '✅ Задачи'!$G$5:$G$1004
Name t_done: '✅ Задачи'!$H$5:$H$1004
Name t_label: '✅ Задачи'!$K$5:$K$1004
Name t_key: '✅ Задачи'!$L$5:$L$1004
Name t_od: '✅ Задачи'!$M$5:$M$1004
Name e_date: '🕘 План дня'!$A$5:$A$3004
Name e_start: '🕘 План дня'!$C$5:$C$3004
Name e_dur: '🕘 План дня'!$E$5:$E$3004
Name e_name: '🕘 План дня'!$F$5:$F$3004
Name e_group: '🕘 План дня'!$G$5:$G$3004
Name e_cat: '🕘 План дня'!$H$5:$H$3004
Name e_status: '🕘 План дня'!$J$5:$J$3004
Name e_label: '🕘 План дня'!$M$5:$M$3004
Name e_key: '🕘 План дня'!$N$5:$N$3004
Name cal_y: '📅 Календарь'!$J$3
Name cal_m: '📅 Календарь'!$K$3

Sheet 🏠 Главная
A1: 🏠 Задачи и календарь 2026 – 2030
A2: Личный задачник: задачи с отметкой выполнения, расписание по времени, календарь месяца и итоги.
B4: 📌 Сводка | E4: ="☀️ Сегодня, "&RIGHT("0"&DAY(TODAY()),2)&"."&RIGHT("0"&MONTH(TODAY()),2)&"."&YEAR(TODAY())&" ("&CHOOSE(WEEKDAY(TODAY(),2),"Пн","Вт","Ср","Чт","Пт","Сб","Вс")&")" | G4: ❗ Просроченные задачи
B5: Всего задач | C5: ='📊 Итоги'!B9 | E5: =IFERROR(IF(1<=COUNTIFS(e_date,$F$5,e_name,"?*"),INDEX(e_label,MATCH($F$5&"#"&1,e_key,0)),IF(1-COUNTIFS(e_date,$F$5,e_name,"?*")<=COUNTIFS(t_date,$F$5,t_name,"?*",t_status,"<>❌ Отменена"),INDEX(t_label,MATCH($F$5&"#"&(1-COUNTIFS(e_date,$F$5,e_name,"?*")),t_key,0)),"")),"") | F5: =TODAY() | G5: =IFERROR(INDEX(t_name,MATCH(1,t_od,0)),"") | H5: =IFERROR(INDEX(t_date,MATCH(1,t_od,0)),"")
B6: ✅ Выполнено | C6: ='📊 Итоги'!B7 | E6: =IFERROR(IF(2<=COUNTIFS(e_date,$F$5,e_name,"?*"),INDEX(e_label,MATCH($F$5&"#"&2,e_key,0)),IF(2-COUNTIFS(e_date,$F$5,e_name,"?*")<=COUNTIFS(t_date,$F$5,t_name,"?*",t_status,"<>❌ Отменена"),INDEX(t_label,MATCH($F$5&"#"&(2-COUNTIFS(e_date,$F$5,e_name,"?*")),t_key,0)),"")),"") | G6: =IFERROR(INDEX(t_name,MATCH(2,t_od,0)),"") | H6: =IFERROR(INDEX(t_date,MATCH(2,t_od,0)),"")
B7: 🎯 Прогресс | C7: =IF(('📊 Итоги'!B9-'📊 Итоги'!B8)=0,"",'📊 Итоги'!B7/('📊 Итоги'!B9-'📊 Итоги'!B8)) | E7: =IFERROR(IF(3<=COUNTIFS(e_date,$F$5,e_name,"?*"),INDEX(e_label,MATCH($F$5&"#"&3,e_key,0)),IF(3-COUNTIFS(e_date,$F$5,e_name,"?*")<=COUNTIFS(t_date,$F$5,t_name,"?*",t_status,"<>❌ Отменена"),INDEX(t_label,MATCH($F$5&"#"&(3-COUNTIFS(e_date,$F$5,e_name,"?*")),t_key,0)),"")),"") | G7: =IFERROR(INDEX(t_name,MATCH(3,t_od,0)),"") | H7: =IFERROR(INDEX(t_date,MATCH(3,t_od,0)),"")
B8: ❗ Просрочено | C8: ='📊 Итоги'!B10 | E8: =IFERROR(IF(4<=COUNTIFS(e_date,$F$5,e_name,"?*"),INDEX(e_label,MATCH($F$5&"#"&4,e_key,0)),IF(4-COUNTIFS(e_date,$F$5,e_name,"?*")<=COUNTIFS(t_date,$F$5,t_name,"?*",t_status,"<>❌ Отменена"),INDEX(t_label,MATCH($F$5&"#"&(4-COUNTIFS(e_date,$F$5,e_name,"?*")),t_key,0)),"")),"") | G8: =IFERROR(INDEX(t_name,MATCH(4,t_od,0)),"") | H8: =IFERROR(INDEX(t_date,MATCH(4,t_od,0)),"")
B9: 🔥 На сегодня (дел + задач) | C9: =COUNTIFS(e_date,TODAY(),e_name,"?*")+COUNTIFS(t_date,TODAY(),t_name,"?*",t_status,"<>❌ Отменена") | E9: =IFERROR(IF(5<=COUNTIFS(e_date,$F$5,e_name,"?*"),INDEX(e_label,MATCH($F$5&"#"&5,e_key,0)),IF(5-COUNTIFS(e_date,$F$5,e_name,"?*")<=COUNTIFS(t_date,$F$5,t_name,"?*",t_status,"<>❌ Отменена"),INDEX(t_label,MATCH($F$5&"#"&(5-COUNTIFS(e_date,$F$5,e_name,"?*")),t_key,0)),"")),"") | G9: =IFERROR(INDEX(t_name,MATCH(5,t_od,0)),"") | H9: =IFERROR(INDEX(t_date,MATCH(5,t_od,0)),"")
B10: ⏱ Часов на этой неделе | C10: =SUMIFS(e_dur,e_date,">="&(TODAY()-WEEKDAY(TODAY(),2)+1),e_date,"<"&(TODAY()-WEEKDAY(TODAY(),2)+8)) | E10: =IFERROR(IF(6<=COUNTIFS(e_date,$F$5,e_name,"?*"),INDEX(e_label,MATCH($F$5&"#"&6,e_key,0)),IF(6-COUNTIFS(e_date,$F$5,e_name,"?*")<=COUNTIFS(t_date,$F$5,t_name,"?*",t_status,"<>❌ Отменена"),INDEX(t_label,MATCH($F$5&"#"&(6-COUNTIFS(e_date,$F$5,e_name,"?*")),t_key,0)),"")),"") | G10: =IFERROR(INDEX(t_name,MATCH(6,t_od,0)),"") | H10: =IFERROR(INDEX(t_date,MATCH(6,t_od,0)),"")
E11: =IFERROR(IF(7<=COUNTIFS(e_date,$F$5,e_name,"?*"),INDEX(e_label,MATCH($F$5&"#"&7,e_key,0)),IF(7-COUNTIFS(e_date,$F$5,e_name,"?*")<=COUNTIFS(t_date,$F$5,t_name,"?*",t_status,"<>❌ Отменена"),INDEX(t_label,MATCH($F$5&"#"&(7-COUNTIFS(e_date,$F$5,e_name,"?*")),t_key,0)),"")),"") | G11: =IFERROR(INDEX(t_name,MATCH(7,t_od,0)),"") | H11: =IFERROR(INDEX(t_date,MATCH(7,t_od,0)),"")
B12: 🧭 Навигация | E12: =IFERROR(IF(8<=COUNTIFS(e_date,$F$5,e_name,"?*"),INDEX(e_label,MATCH($F$5&"#"&8,e_key,0)),IF(8-COUNTIFS(e_date,$F$5,e_name,"?*")<=COUNTIFS(t_date,$F$5,t_name,"?*",t_status,"<>❌ Отменена"),INDEX(t_label,MATCH($F$5&"#"&(8-COUNTIFS(e_date,$F$5,e_name,"?*")),t_key,0)),"")),"") | G12: =IFERROR(INDEX(t_name,MATCH(8,t_od,0)),"") | H12: =IFERROR(INDEX(t_date,MATCH(8,t_od,0)),"")
B13: 📅 Календарь | C13: календарь месяца | E13: =IFERROR(IF(9<=COUNTIFS(e_date,$F$5,e_name,"?*"),INDEX(e_label,MATCH($F$5&"#"&9,e_key,0)),IF(9-COUNTIFS(e_date,$F$5,e_name,"?*")<=COUNTIFS(t_date,$F$5,t_name,"?*",t_status,"<>❌ Отменена"),INDEX(t_label,MATCH($F$5&"#"&(9-COUNTIFS(e_date,$F$5,e_name,"?*")),t_key,0)),"")),"") | G13: =IFERROR(INDEX(t_name,MATCH(9,t_od,0)),"") | H13: =IFERROR(INDEX(t_date,MATCH(9,t_od,0)),"")
B14: ✅ Задачи | C14: задачи и отметка выполнения | E14: =IFERROR(IF(10<=COUNTIFS(e_date,$F$5,e_name,"?*"),INDEX(e_label,MATCH($F$5&"#"&10,e_key,0)),IF(10-COUNTIFS(e_date,$F$5,e_name,"?*")<=COUNTIFS(t_date,$F$5,t_name,"?*",t_status,"<>❌ Отменена"),INDEX(t_label,MATCH($F$5&"#"&(10-COUNTIFS(e_date,$F$5,e_name,"?*")),t_key,0)),"")),"") | G14: =IFERROR(INDEX(t_name,MATCH(10,t_od,0)),"") | H14: =IFERROR(INDEX(t_date,MATCH(10,t_od,0)),"")
B15: 🕘 План дня | C15: расписание по времени | E15: =IFERROR(IF(11<=COUNTIFS(e_date,$F$5,e_name,"?*"),INDEX(e_label,MATCH($F$5&"#"&11,e_key,0)),IF(11-COUNTIFS(e_date,$F$5,e_name,"?*")<=COUNTIFS(t_date,$F$5,t_name,"?*",t_status,"<>❌ Отменена"),INDEX(t_label,MATCH($F$5&"#"&(11-COUNTIFS(e_date,$F$5,e_name,"?*")),t_key,0)),"")),"") | G15: =IF(COUNT(t_od)>10,"… и ещё "&(COUNT(t_od)-10),IF(COUNT(t_od)=0,"🎉 Просроченных нет!",""))
B16: 📊 Итоги | C16: итоги по группам и категориям | E16: =IFERROR(IF(COUNTIFS(e_date,$F$5,e_name,"?*")+COUNTIFS(t_date,$F$5,t_name,"?*",t_status,"<>❌ Отменена")>12,"… ещё "&(COUNTIFS(e_date,$F$5,e_name,"?*")+COUNTIFS(t_date,$F$5,t_name,"?*",t_status,"<>❌ Отменена")-11),IF(12<=COUNTIFS(e_date,$F$5,e_name,"?*"),INDEX(e_label,MATCH($F$5&"#"&12,e_key,0)),IF(12-COUNTIFS(e_date,$F$5,e_name,"?*")<=COUNTIFS(t_date,$F$5,t_name,"?*",t_status,"<>❌ Отменена"),INDEX(t_label,MATCH($F$5&"#"&(12-COUNTIFS(e_date,$F$5,e_name,"?*")),t_key,0)),""))),"")
B17: 🗓 По месяцам | C17: итоги по месяцам + графики | E17: Пусто? Добавьте дела в «🕘 План дня» и задачи со сроком на сегодня.
B18: 📚 Справочник | C18: справочник списков
B20: 🎨 Как пользоваться
B21: 1️⃣ «✅ Задачи» — записываете задачи: группа, категория, приоритет, срок. Выполнили → статус «✅ Выполнена».
B22: 2️⃣ «🕘 План дня» — расписание: дата, начало, конец, дело. Сделали → статус «✅ Сделано».
B23: 3️⃣ «📅 Календарь» — выберите год и месяц: в каждом дне видны дела и задачи.
B24: 4️⃣ «📊 Итоги» и «🗓 По месяцам» — считаются сами, вводить ничего не нужно.
B25: 🟢 Зелёные вкладки — витрины (смотреть), 🔴 красные — технические (вводить данные).
B26: Жёлтые ячейки — ввод. Синий шрифт — ваши данные. Зачёркнуто — выполнено. Красным — просрочено.
B27: В «Задачах» и «Плане дня» есть строки-ПРИМЕРЫ — замените или удалите их.

Sheet 📅 Календарь
A1: 📅 Календарь
A2: Выберите год и месяц в жёлтых ячейках (пусто = текущий месяц). В каждом дне — дела из «🕘 План дня» (по времени) и задачи из «✅ Задачи» (по сроку). ✔ — сделано, ❗ — просрочено, ☐ — в планах.
B3: 📆 Год ▸ | D3: 🗓 Месяц ▸ | J3: =IF($C$3="",YEAR(TODAY()),$C$3) | K3: =IF($E$3="",MONTH(TODAY()),MATCH($E$3,lst_months,0))
B4: =INDEX(lst_months,cal_m)&" "&cal_y
B5: Пн | C5: Вт | D5: Ср | E5: Чт | F5: Пт | G5: Сб | H5: Вс
B6: =(DATE(cal_y,cal_m,1)-WEEKDAY(DATE(cal_y,cal_m,1),2)+1)+0 | C6: =(DATE(cal_y,cal_m,1)-WEEKDAY(DATE(cal_y,cal_m,1),2)+1)+1 | D6: =(DATE(cal_y,cal_m,1)-WEEKDAY(DATE(cal_y,cal_m,1),2)+1)+2 | E6: =(DATE(cal_y,cal_m,1)-WEEKDAY(DATE(cal_y,cal_m,1),2)+1)+3 | F6: =(DATE(cal_y,cal_m,1)-WEEKDAY(DATE(cal_y,cal_m,1),2)+1)+4 | G6: =(DATE(cal_y,cal_m,1)-WEEKDAY(DATE(cal_y,cal_m,1),2)+1)+5 | H6: =(DATE(cal_y,cal_m,1)-WEEKDAY(DATE(cal_y,cal_m,1),2)+1)+6 | J6: 📊 Этот месяц
B7: =IFERROR(IF(1<=COUNTIFS(e_date,B$6,e_name,"?*"),INDEX(e_label,MATCH(B$6&"#"&1,e_key,0)),IF(1-COUNTIFS(e_date,B$6,e_name,"?*")<=COUNTIFS(t_date,B$6,t_name,"?*",t_status,"<>❌ Отменена"),INDEX(t_label,MATCH(B$6&"#"&(1-COUNTIFS(e_date,B$6,e_name,"?*")),t_key,0)),"")),"") | C7: =IFERROR(IF(1<=COUNTIFS(e_date,C$6,e_name,"?*"),INDEX(e_label,MATCH(C$6&"#"&1,e_key,0)),IF(1-COUNTIFS(e_date,C$6,e_name,"?*")<=COUNTIFS(t_date,C$6,t_name,"?*",t_status,"<>❌ Отменена"),INDEX(t_label,MATCH(C$6&"#"&(1-COUNTIFS(e_date,C$6,e_name,"?*")),t_key,0)),"")),"") | D7: =IFERROR(IF(1<=COUNTIFS(e_date,D$6,e_name,"?*"),INDEX(e_label,MATCH(D$6&"#"&1,e_key,0)),IF(1-COUNTIFS(e_date,D$6,e_name,"?*")<=COUNTIFS(t_date,D$6,t_name,"?*",t_status,"<>❌ Отменена"),INDEX(t_label,MATCH(D$6&"#"&(1-COUNTIFS(e_date,D$6,e_name,"?*")),t_key,0)),"")),"") | E7: =IFERROR(IF(1<=COUNTIFS(e_date,E$6,e_name,"?*"),INDEX(e_label,MATCH(E$6&"#"&1,e_key,0)),IF(1-COUNTIFS(e_date,E$6,e_name,"?*")<=COUNTIFS(t_date,E$6,t_name,"?*",t_status,"<>❌ Отменена"),INDEX(t_label,MATCH(E$6&"#"&(1-COUNTIFS(e_date,E$6,e_name,"?*")),t_key,0)),"")),"") | F7: =IFERROR(IF(1<=COUNTIFS(e_date,F$6,e_name,"?*"),INDEX(e_label,MATCH(F$6&"#"&1,e_key,0)),IF(1-COUNTIFS(e_date,F$6,e_name,"?*")<=COUNTIFS(t_date,F$6,t_name,"?*",t_status,"<>❌ Отменена"),INDEX(t_label,MATCH(F$6&"#"&(1-COUNTIFS(e_date,F$6,e_name,"?*")),t_key,0)),"")),"") | G7: =IFERROR(IF(1<=COUNTIFS(e_date,G$6,e_name,"?*"),INDEX(e_label,MATCH(G$6&"#"&1,e_key,0)),IF(1-COUNTIFS(e_date,G$6,e_name,"?*")<=COUNTIFS(t_date,G$6,t_name,"?*",t_status,"<>❌ Отменена"),INDEX(t_label,MATCH(G$6&"#"&(1-COUNTIFS(e_date,G$6,e_name,"?*")),t_key,0)),"")),"") | H7: =IFERROR(IF(1<=COUNTIFS(e_date,H$6,e_name,"?*"),INDEX(e_label,MATCH(H$6&"#"&1,e_key,0)),IF(1-COUNTIFS(e_date,H$6,e_name,"?*")<=COUNTIFS(t_date,H$6,t_name,"?*",t_status,"<>❌ Отменена"),INDEX(t_label,MATCH(H$6&"#"&(1-COUNTIFS(e_date,H$6,e_name,"?*")),t_key,0)),"")),"") | J7: Задач со сроком | K7: =COUNTIFS(t_date,">="&DATE(cal_y,cal_m,1),t_date,"<"&DATE(cal_y,cal_m+1,1),t_name,"?*",t_status,"<>❌ Отменена")
B8: =IFERROR(IF(2<=COUNTIFS(e_date,B$6,e_name,"?*"),INDEX(e_label,MATCH(B$6&"#"&2,e_key,0)),IF(2-COUNTIFS(e_date,B$6,e_name,"?*")<=COUNTIFS(t_date,B$6,t_name,"?*",t_status,"<>❌ Отменена"),INDEX(t_label,MATCH(B$6&"#"&(2-COUNTIFS(e_date,B$6,e_name,"?*")),t_key,0)),"")),"") | C8: =IFERROR(IF(2<=COUNTIFS(e_date,C$6,e_name,"?*"),INDEX(e_label,MATCH(C$6&"#"&2,e_key,0)),IF(2-COUNTIFS(e_date,C$6,e_name,"?*")<=COUNTIFS(t_date,C$6,t_name,"?*",t_status,"<>❌ Отменена"),INDEX(t_label,MATCH(C$6&"#"&(2-COUNTIFS(e_date,C$6,e_name,"?*")),t_key,0)),"")),"") | D8: =IFERROR(IF(2<=COUNTIFS(e_date,D$6,e_name,"?*"),INDEX(e_label,MATCH(D$6&"#"&2,e_key,0)),IF(2-COUNTIFS(e_date,D$6,e_name,"?*")<=COUNTIFS(t_date,D$6,t_name,"?*",t_status,"<>❌ Отменена"),INDEX(t_label,MATCH(D$6&"#"&(2-COUNTIFS(e_date,D$6,e_name,"?*")),t_key,0)),"")),"") | E8: =IFERROR(IF(2<=COUNTIFS(e_date,E$6,e_name,"?*"),INDEX(e_label,MATCH(E$6&"#"&2,e_key,0)),IF(2-COUNTIFS(e_date,E$6,e_name,"?*")<=COUNTIFS(t_date,E$6,t_name,"?*",t_status,"<>❌ Отменена"),INDEX(t_label,MATCH(E$6&"#"&(2-COUNTIFS(e_date,E$6,e_name,"?*")),t_key,0)),"")),"") | F8: =IFERROR(IF(2<=COUNTIFS(e_date,F$6,e_name,"?*"),INDEX(e_label,MATCH(F$6&"#"&2,e_key,0)),IF(2-COUNTIFS(e_date,F$6,e_name,"?*")<=COUNTIFS(t_date,F$6,t_name,"?*",t_status,"<>❌ Отменена"),INDEX(t_label,MATCH(F$6&"#"&(2-COUNTIFS(e_date,F$6,e_name,"?*")),t_key,0)),"")),"") | G8: =IFERROR(IF(2<=COUNTIFS(e_date,G$6,e_name,"?*"),INDEX(e_label,MATCH(G$6&"#"&2,e_key,0)),IF(2-COUNTIFS(e_date,G$6,e_name,"?*")<=COUNTIFS(t_date,G$6,t_name,"?*",t_status,"<>❌ Отменена"),INDEX(t_label,MATCH(G$6&"#"&(2-COUNTIFS(e_date,G$6,e_name,"?*")),t_key,0)),"")),"") | H8: =IFERROR(IF(2<=COUNTIFS(e_date,H$6,e_name,"?*"),INDEX(e_label,MATCH(H$6&"#"&2,e_key,0)),IF(2-COUNTIFS(e_date,H$6,e_name,"?*")<=COUNTIFS(t_date,H$6,t_name,"?*",t_status,"<>❌ Отменена"),INDEX(t_label,MATCH(H$6&"#"&(2-COUNTIFS(e_date,H$6,e_name,"?*")),t_key,0)),"")),"") | J8: ✅ Выполнено | K8: =COUNTIFS(t_date,">="&DATE(cal_y,cal_m,1),t_date,"<"&DATE(cal_y,cal_m+1,1),t_status,"✅ Выполнена")
B9: =IFERROR(IF(3<=COUNTIFS(e_date,B$6,e_name,"?*"),INDEX(e_label,MATCH(B$6&"#"&3,e_key,0)),IF(3-COUNTIFS(e_date,B$6,e_name,"?*")<=COUNTIFS(t_date,B$6,t_name,"?*",t_status,"<>❌ Отменена"),INDEX(t_label,MATCH(B$6&"#"&(3-COUNTIFS(e_date,B$6,e_name,"?*")),t_key,0)),"")),"") | C9: =IFERROR(IF(3<=COUNTIFS(e_date,C$6,e_name,"?*"),INDEX(e_label,MATCH(C$6&"#"&3,e_key,0)),IF(3-COUNTIFS(e_date,C$6,e_name,"?*")<=COUNTIFS(t_date,C$6,t_name,"?*",t_status,"<>❌ Отменена"),INDEX(t_label,MATCH(C$6&"#"&(3-COUNTIFS(e_date,C$6,e_name,"?*")),t_key,0)),"")),"") | D9: =IFERROR(IF(3<=COUNTIFS(e_date,D$6,e_name,"?*"),INDEX(e_label,MATCH(D$6&"#"&3,e_key,0)),IF(3-COUNTIFS(e_date,D$6,e_name,"?*")<=COUNTIFS(t_date,D$6,t_name,"?*",t_status,"<>❌ Отменена"),INDEX(t_label,MATCH(D$6&"#"&(3-COUNTIFS(e_date,D$6,e_name,"?*")),t_key,0)),"")),"") | E9: =IFERROR(IF(3<=COUNTIFS(e_date,E$6,e_name,"?*"),INDEX(e_label,MATCH(E$6&"#"&3,e_key,0)),IF(3-COUNTIFS(e_date,E$6,e_name,"?*")<=COUNTIFS(t_date,E$6,t_name,"?*",t_status,"<>❌ Отменена"),INDEX(t_label,MATCH(E$6&"#"&(3-COUNTIFS(e_date,E$6,e_name,"?*")),t_key,0)),"")),"") | F9: =IFERROR(IF(3<=COUNTIFS(e_date,F$6,e_name,"?*"),INDEX(e_label,MATCH(F$6&"#"&3,e_key,0)),IF(3-COUNTIFS(e_date,F$6,e_name,"?*")<=COUNTIFS(t_date,F$6,t_name,"?*",t_status,"<>❌ Отменена"),INDEX(t_label,MATCH(F$6&"#"&(3-COUNTIFS(e_date,F$6,e_name,"?*")),t_key,0)),"")),"") | G9: =IFERROR(IF(3<=COUNTIFS(e_date,G$6,e_name,"?*"),INDEX(e_label,MATCH(G$6&"#"&3,e_key,0)),IF(3-COUNTIFS(e_date,G$6,e_name,"?*")<=COUNTIFS(t_date,G$6,t_name,"?*",t_status,"<>❌ Отменена"),INDEX(t_label,MATCH(G$6&"#"&(3-COUNTIFS(e_date,G$6,e_name,"?*")),t_key,0)),"")),"") | H9: =IFERROR(IF(3<=COUNTIFS(e_date,H$6,e_name,"?*"),INDEX(e_label,MATCH(H$6&"#"&3,e_key,0)),IF(3-COUNTIFS(e_date,H$6,e_name,"?*")<=COUNTIFS(t_date,H$6,t_name,"?*",t_status,"<>❌ Отменена"),INDEX(t_label,MATCH(H$6&"#"&(3-COUNTIFS(e_date,H$6,e_name,"?*")),t_key,0)),"")),"") | J9: 🎯 Прогресс | K9: =IF(K7=0,"",K8/K7)
B10: =IFERROR(IF(4<=COUNTIFS(e_date,B$6,e_name,"?*"),INDEX(e_label,MATCH(B$6&"#"&4,e_key,0)),IF(4-COUNTIFS(e_date,B$6,e_name,"?*")<=COUNTIFS(t_date,B$6,t_name,"?*",t_status,"<>❌ Отменена"),INDEX(t_label,MATCH(B$6&"#"&(4-COUNTIFS(e_date,B$6,e_name,"?*")),t_key,0)),"")),"") | C10: =IFERROR(IF(4<=COUNTIFS(e_date,C$6,e_name,"?*"),INDEX(e_label,MATCH(C$6&"#"&4,e_key,0)),IF(4-COUNTIFS(e_date,C$6,e_name,"?*")<=COUNTIFS(t_date,C$6,t_name,"?*",t_status,"<>❌ Отменена"),INDEX(t_label,MATCH(C$6&"#"&(4-COUNTIFS(e_date,C$6,e_name,"?*")),t_key,0)),"")),"") | D10: =IFERROR(IF(4<=COUNTIFS(e_date,D$6,e_name,"?*"),INDEX(e_label,MATCH(D$6&"#"&4,e_key,0)),IF(4-COUNTIFS(e_date,D$6,e_name,"?*")<=COUNTIFS(t_date,D$6,t_name,"?*",t_status,"<>❌ Отменена"),INDEX(t_label,MATCH(D$6&"#"&(4-COUNTIFS(e_date,D$6,e_name,"?*")),t_key,0)),"")),"") | E10: =IFERROR(IF(4<=COUNTIFS(e_date,E$6,e_name,"?*"),INDEX(e_label,MATCH(E$6&"#"&4,e_key,0)),IF(4-COUNTIFS(e_date,E$6,e_name,"?*")<=COUNTIFS(t_date,E$6,t_name,"?*",t_status,"<>❌ Отменена"),INDEX(t_label,MATCH(E$6&"#"&(4-COUNTIFS(e_date,E$6,e_name,"?*")),t_key,0)),"")),"") | F10: =IFERROR(IF(4<=COUNTIFS(e_date,F$6,e_name,"?*"),INDEX(e_label,MATCH(F$6&"#"&4,e_key,0)),IF(4-COUNTIFS(e_date,F$6,e_name,"?*")<=COUNTIFS(t_date,F$6,t_name,"?*",t_status,"<>❌ Отменена"),INDEX(t_label,MATCH(F$6&"#"&(4-COUNTIFS(e_date,F$6,e_name,"?*")),t_key,0)),"")),"") | G10: =IFERROR(IF(4<=COUNTIFS(e_date,G$6,e_name,"?*"),INDEX(e_label,MATCH(G$6&"#"&4,e_key,0)),IF(4-COUNTIFS(e_date,G$6,e_name,"?*")<=COUNTIFS(t_date,G$6,t_name,"?*",t_status,"<>❌ Отменена"),INDEX(t_label,MATCH(G$6&"#"&(4-COUNTIFS(e_date,G$6,e_name,"?*")),t_key,0)),"")),"") | H10: =IFERROR(IF(4<=COUNTIFS(e_date,H$6,e_name,"?*"),INDEX(e_label,MATCH(H$6&"#"&4,e_key,0)),IF(4-COUNTIFS(e_date,H$6,e_name,"?*")<=COUNTIFS(t_date,H$6,t_name,"?*",t_status,"<>❌ Отменена"),INDEX(t_label,MATCH(H$6&"#"&(4-COUNTIFS(e_date,H$6,e_name,"?*")),t_key,0)),"")),"") | J10: ❗ Просрочено | K10: =COUNTIFS(t_date,">="&DATE(cal_y,cal_m,1),t_date,"<"&DATE(cal_y,cal_m+1,1),t_od,">0")
B11: =IFERROR(IF(5<=COUNTIFS(e_date,B$6,e_name,"?*"),INDEX(e_label,MATCH(B$6&"#"&5,e_key,0)),IF(5-COUNTIFS(e_date,B$6,e_name,"?*")<=COUNTIFS(t_date,B$6,t_name,"?*",t_status,"<>❌ Отменена"),INDEX(t_label,MATCH(B$6&"#"&(5-COUNTIFS(e_date,B$6,e_name,"?*")),t_key,0)),"")),"") | C11: =IFERROR(IF(5<=COUNTIFS(e_date,C$6,e_name,"?*"),INDEX(e_label,MATCH(C$6&"#"&5,e_key,0)),IF(5-COUNTIFS(e_date,C$6,e_name,"?*")<=COUNTIFS(t_date,C$6,t_name,"?*",t_status,"<>❌ Отменена"),INDEX(t_label,MATCH(C$6&"#"&(5-COUNTIFS(e_date,C$6,e_name,"?*")),t_key,0)),"")),"") | D11: =IFERROR(IF(5<=COUNTIFS(e_date,D$6,e_name,"?*"),INDEX(e_label,MATCH(D$6&"#"&5,e_key,0)),IF(5-COUNTIFS(e_date,D$6,e_name,"?*")<=COUNTIFS(t_date,D$6,t_name,"?*",t_status,"<>❌ Отменена"),INDEX(t_label,MATCH(D$6&"#"&(5-COUNTIFS(e_date,D$6,e_name,"?*")),t_key,0)),"")),"") | E11: =IFERROR(IF(5<=COUNTIFS(e_date,E$6,e_name,"?*"),INDEX(e_label,MATCH(E$6&"#"&5,e_key,0)),IF(5-COUNTIFS(e_date,E$6,e_name,"?*")<=COUNTIFS(t_date,E$6,t_name,"?*",t_status,"<>❌ Отменена"),INDEX(t_label,MATCH(E$6&"#"&(5-COUNTIFS(e_date,E$6,e_name,"?*")),t_key,0)),"")),"") | F11: =IFERROR(IF(5<=COUNTIFS(e_date,F$6,e_name,"?*"),INDEX(e_label,MATCH(F$6&"#"&5,e_key,0)),IF(5-COUNTIFS(e_date,F$6,e_name,"?*")<=COUNTIFS(t_date,F$6,t_name,"?*",t_status,"<>❌ Отменена"),INDEX(t_label,MATCH(F$6&"#"&(5-COUNTIFS(e_date,F$6,e_name,"?*")),t_key,0)),"")),"") | G11: =IFERROR(IF(5<=COUNTIFS(e_date,G$6,e_name,"?*"),INDEX(e_label,MATCH(G$6&"#"&5,e_key,0)),IF(5-COUNTIFS(e_date,G$6,e_name,"?*")<=COUNTIFS(t_date,G$6,t_name,"?*",t_status,"<>❌ Отменена"),INDEX(t_label,MATCH(G$6&"#"&(5-COUNTIFS(e_date,G$6,e_name,"?*")),t_key,0)),"")),"") | H11: =IFERROR(IF(5<=COUNTIFS(e_date,H$6,e_name,"?*"),INDEX(e_label,MATCH(H$6&"#"&5,e_key,0)),IF(5-COUNTIFS(e_date,H$6,e_name,"?*")<=COUNTIFS(t_date,H$6,t_name,"?*",t_status,"<>❌ Отменена"),INDEX(t_label,MATCH(H$6&"#"&(5-COUNTIFS(e_date,H$6,e_name,"?*")),t_key,0)),"")),"") | J11: 🕘 Дел в расписании | K11: =COUNTIFS(e_date,">="&DATE(cal_y,cal_m,1),e_date,"<"&DATE(cal_y,cal_m+1,1),e_name,"?*")
B12: =IFERROR(IF(COUNTIFS(e_date,B$6,e_name,"?*")+COUNTIFS(t_date,B$6,t_name,"?*",t_status,"<>❌ Отменена")>6,"… ещё "&(COUNTIFS(e_date,B$6,e_name,"?*")+COUNTIFS(t_date,B$6,t_name,"?*",t_status,"<>❌ Отменена")-5),IF(6<=COUNTIFS(e_date,B$6,e_name,"?*"),INDEX(e_label,MATCH(B$6&"#"&6,e_key,0)),IF(6-COUNTIFS(e_date,B$6,e_name,"?*")<=COUNTIFS(t_date,B$6,t_name,"?*",t_status,"<>❌ Отменена"),INDEX(t_label,MATCH(B$6&"#"&(6-COUNTIFS(e_date,B$6,e_name,"?*")),t_key,0)),""))),"") | C12: =IFERROR(IF(COUNTIFS(e_date,C$6,e_name,"?*")+COUNTIFS(t_date,C$6,t_name,"?*",t_status,"<>❌ Отменена")>6,"… ещё "&(COUNTIFS(e_date,C$6,e_name,"?*")+COUNTIFS(t_date,C$6,t_name,"?*",t_status,"<>❌ Отменена")-5),IF(6<=COUNTIFS(e_date,C$6,e_name,"?*"),INDEX(e_label,MATCH(C$6&"#"&6,e_key,0)),IF(6-COUNTIFS(e_date,C$6,e_name,"?*")<=COUNTIFS(t_date,C$6,t_name,"?*",t_status,"<>❌ Отменена"),INDEX(t_label,MATCH(C$6&"#"&(6-COUNTIFS(e_date,C$6,e_name,"?*")),t_key,0)),""))),"") | D12: =IFERROR(IF(COUNTIFS(e_date,D$6,e_name,"?*")+COUNTIFS(t_date,D$6,t_name,"?*",t_status,"<>❌ Отменена")>6,"… ещё "&(COUNTIFS(e_date,D$6,e_name,"?*")+COUNTIFS(t_date,D$6,t_name,"?*",t_status,"<>❌ Отменена")-5),IF(6<=COUNTIFS(e_date,D$6,e_name,"?*"),INDEX(e_label,MATCH(D$6&"#"&6,e_key,0)),IF(6-COUNTIFS(e_date,D$6,e_name,"?*")<=COUNTIFS(t_date,D$6,t_name,"?*",t_status,"<>❌ Отменена"),INDEX(t_label,MATCH(D$6&"#"&(6-COUNTIFS(e_date,D$6,e_name,"?*")),t_key,0)),""))),"") | E12: =IFERROR(IF(COUNTIFS(e_date,E$6,e_name,"?*")+COUNTIFS(t_date,E$6,t_name,"?*",t_status,"<>❌ Отменена")>6,"… ещё "&(COUNTIFS(e_date,E$6,e_name,"?*")+COUNTIFS(t_date,E$6,t_name,"?*",t_status,"<>❌ Отменена")-5),IF(6<=COUNTIFS(e_date,E$6,e_name,"?*"),INDEX(e_label,MATCH(E$6&"#"&6,e_key,0)),IF(6-COUNTIFS(e_date,E$6,e_name,"?*")<=COUNTIFS(t_date,E$6,t_name,"?*",t_status,"<>❌ Отменена"),INDEX(t_label,MATCH(E$6&"#"&(6-COUNTIFS(e_date,E$6,e_name,"?*")),t_key,0)),""))),"") | F12: =IFERROR(IF(COUNTIFS(e_date,F$6,e_name,"?*")+COUNTIFS(t_date,F$6,t_name,"?*",t_status,"<>❌ Отменена")>6,"… ещё "&(COUNTIFS(e_date,F$6,e_name,"?*")+COUNTIFS(t_date,F$6,t_name,"?*",t_status,"<>❌ Отменена")-5),IF(6<=COUNTIFS(e_date,F$6,e_name,"?*"),INDEX(e_label,MATCH(F$6&"#"&6,e_key,0)),IF(6-COUNTIFS(e_date,F$6,e_name,"?*")<=COUNTIFS(t_date,F$6,t_name,"?*",t_status,"<>❌ Отменена"),INDEX(t_label,MATCH(F$6&"#"&(6-COUNTIFS(e_date,F$6,e_name,"?*")),t_key,0)),""))),"") | G12: =IFERROR(IF(COUNTIFS(e_date,G$6,e_name,"?*")+COUNTIFS(t_date,G$6,t_name,"?*",t_status,"<>❌ Отменена")>6,"… ещё "&(COUNTIFS(e_date,G$6,e_name,"?*")+COUNTIFS(t_date,G$6,t_name,"?*",t_status,"<>❌ Отменена")-5),IF(6<=COUNTIFS(e_date,G$6,e_name,"?*"),INDEX(e_label,MATCH(G$6&"#"&6,e_key,0)),IF(6-COUNTIFS(e_date,G$6,e_name,"?*")<=COUNTIFS(t_date,G$6,t_name,"?*",t_status,"<>❌ Отменена"),INDEX(t_label,MATCH(G$6&"#"&(6-COUNTIFS(e_date,G$6,e_name,"?*")),t_key,0)),""))),"") | H12: =IFERROR(IF(COUNTIFS(e_date,H$6,e_name,"?*")+COUNTIFS(t_date,H$6,t_name,"?*",t_status,"<>❌ Отменена")>6,"… ещё "&(COUNTIFS(e_date,H$6,e_name,"?*")+COUNTIFS(t_date,H$6,t_name,"?*",t_status,"<>❌ Отменена")-5),IF(6<=COUNTIFS(e_date,H$6,e_name,"?*"),INDEX(e_label,MATCH(H$6&"#"&6,e_key,0)),IF(6-COUNTIFS(e_date,H$6,e_name,"?*")<=COUNTIFS(t_date,H$6,t_name,"?*",t_status,"<>❌ Отменена"),INDEX(t_label,MATCH(H$6&"#"&(6-COUNTIFS(e_date,H$6,e_name,"?*")),t_key,0)),""))),"") | J12: ⏱ Часов запланировано | K12: =SUMIFS(e_dur,e_date,">="&DATE(cal_y,cal_m,1),e_date,"<"&DATE(cal_y,cal_m+1,1))
B13: =(DATE(cal_y,cal_m,1)-WEEKDAY(DATE(cal_y,cal_m,1),2)+1)+7 | C13: =(DATE(cal_y,cal_m,1)-WEEKDAY(DATE(cal_y,cal_m,1),2)+1)+8 | D13: =(DATE(cal_y,cal_m,1)-WEEKDAY(DATE(cal_y,cal_m,1),2)+1)+9 | E13: =(DATE(cal_y,cal_m,1)-WEEKDAY(DATE(cal_y,cal_m,1),2)+1)+10 | F13: =(DATE(cal_y,cal_m,1)-WEEKDAY(DATE(cal_y,cal_m,1),2)+1)+11 | G13: =(DATE(cal_y,cal_m,1)-WEEKDAY(DATE(cal_y,cal_m,1),2)+1)+12 | H13: =(DATE(cal_y,cal_m,1)-WEEKDAY(DATE(cal_y,cal_m,1),2)+1)+13 | J13: ⏱ Часов сделано | K13: =SUMIFS(e_dur,e_date,">="&DATE(cal_y,cal_m,1),e_date,"<"&DATE(cal_y,cal_m+1,1),e_status,"✅ Сделано")
B14: =IFERROR(IF(1<=COUNTIFS(e_date,B$13,e_name,"?*"),INDEX(e_label,MATCH(B$13&"#"&1,e_key,0)),IF(1-COUNTIFS(e_date,B$13,e_name,"?*")<=COUNTIFS(t_date,B$13,t_name,"?*",t_status,"<>❌ Отменена"),INDEX(t_label,MATCH(B$13&"#"&(1-COUNTIFS(e_date,B$13,e_name,"?*")),t_key,0)),"")),"") | C14: =IFERROR(IF(1<=COUNTIFS(e_date,C$13,e_name,"?*"),INDEX(e_label,MATCH(C$13&"#"&1,e_key,0)),IF(1-COUNTIFS(e_date,C$13,e_name,"?*")<=COUNTIFS(t_date,C$13,t_name,"?*",t_status,"<>❌ Отменена"),INDEX(t_label,MATCH(C$13&"#"&(1-COUNTIFS(e_date,C$13,e_name,"?*")),t_key,0)),"")),"") | D14: =IFERROR(IF(1<=COUNTIFS(e_date,D$13,e_name,"?*"),INDEX(e_label,MATCH(D$13&"#"&1,e_key,0)),IF(1-COUNTIFS(e_date,D$13,e_name,"?*")<=COUNTIFS(t_date,D$13,t_name,"?*",t_status,"<>❌ Отменена"),INDEX(t_label,MATCH(D$13&"#"&(1-COUNTIFS(e_date,D$13,e_name,"?*")),t_key,0)),"")),"") | E14: =IFERROR(IF(1<=COUNTIFS(e_date,E$13,e_name,"?*"),INDEX(e_label,MATCH(E$13&"#"&1,e_key,0)),IF(1-COUNTIFS(e_date,E$13,e_name,"?*")<=COUNTIFS(t_date,E$13,t_name,"?*",t_status,"<>❌ Отменена"),INDEX(t_label,MATCH(E$13&"#"&(1-COUNTIFS(e_date,E$13,e_name,"?*")),t_key,0)),"")),"") | F14: =IFERROR(IF(1<=COUNTIFS(e_date,F$13,e_name,"?*"),INDEX(e_label,MATCH(F$13&"#"&1,e_key,0)),IF(1-COUNTIFS(e_date,F$13,e_name,"?*")<=COUNTIFS(t_date,F$13,t_name,"?*",t_status,"<>❌ Отменена"),INDEX(t_label,MATCH(F$13&"#"&(1-COUNTIFS(e_date,F$13,e_name,"?*")),t_key,0)),"")),"") | G14: =IFERROR(IF(1<=COUNTIFS(e_date,G$13,e_name,"?*"),INDEX(e_label,MATCH(G$13&"#"&1,e_key,0)),IF(1-COUNTIFS(e_date,G$13,e_name,"?*")<=COUNTIFS(t_date,G$13,t_name,"?*",t_status,"<>❌ Отменена"),INDEX(t_label,MATCH(G$13&"#"&(1-COUNTIFS(e_date,G$13,e_name,"?*")),t_key,0)),"")),"") | H14: =IFERROR(IF(1<=COUNTIFS(e_date,H$13,e_name,"?*"),INDEX(e_label,MATCH(H$13&"#"&1,e_key,0)),IF(1-COUNTIFS(e_date,H$13,e_name,"?*")<=COUNTIFS(t_date,H$13,t_name,"?*",t_status,"<>❌ Отменена"),INDEX(t_label,MATCH(H$13&"#"&(1-COUNTIFS(e_date,H$13,e_name,"?*")),t_key,0)),"")),"")
B15: =IFERROR(IF(2<=COUNTIFS(e_date,B$13,e_name,"?*"),INDEX(e_label,MATCH(B$13&"#"&2,e_key,0)),IF(2-COUNTIFS(e_date,B$13,e_name,"?*")<=COUNTIFS(t_date,B$13,t_name,"?*",t_status,"<>❌ Отменена"),INDEX(t_label,MATCH(B$13&"#"&(2-COUNTIFS(e_date,B$13,e_name,"?*")),t_key,0)),"")),"") | C15: =IFERROR(IF(2<=COUNTIFS(e_date,C$13,e_name,"?*"),INDEX(e_label,MATCH(C$13&"#"&2,e_key,0)),IF(2-COUNTIFS(e_date,C$13,e_name,"?*")<=COUNTIFS(t_date,C$13,t_name,"?*",t_status,"<>❌ Отменена"),INDEX(t_label,MATCH(C$13&"#"&(2-COUNTIFS(e_date,C$13,e_name,"?*")),t_key,0)),"")),"") | D15: =IFERROR(IF(2<=COUNTIFS(e_date,D$13,e_name,"?*"),INDEX(e_label,MATCH(D$13&"#"&2,e_key,0)),IF(2-COUNTIFS(e_date,D$13,e_name,"?*")<=COUNTIFS(t_date,D$13,t_name,"?*",t_status,"<>❌ Отменена"),INDEX(t_label,MATCH(D$13&"#"&(2-COUNTIFS(e_date,D$13,e_name,"?*")),t_key,0)),"")),"") | E15: =IFERROR(IF(2<=COUNTIFS(e_date,E$13,e_name,"?*"),INDEX(e_label,MATCH(E$13&"#"&2,e_key,0)),IF(2-COUNTIFS(e_date,E$13,e_name,"?*")<=COUNTIFS(t_date,E$13,t_name,"?*",t_status,"<>❌ Отменена"),INDEX(t_label,MATCH(E$13&"#"&(2-COUNTIFS(e_date,E$13,e_name,"?*")),t_key,0)),"")),"") | F15: =IFERROR(IF(2<=COUNTIFS(e_date,F$13,e_name,"?*"),INDEX(e_label,MATCH(F$13&"#"&2,e_key,0)),IF(2-COUNTIFS(e_date,F$13,e_name,"?*")<=COUNTIFS(t_date,F$13,t_name,"?*",t_status,"<>❌ Отменена"),INDEX(t_label,MATCH(F$13&"#"&(2-COUNTIFS(e_date,F$13,e_name,"?*")),t_key,0)),"")),"") | G15: =IFERROR(IF(2<=COUNTIFS(e_date,G$13,e_name,"?*"),INDEX(e_label,MATCH(G$13&"#"&2,e_key,0)),IF(2-COUNTIFS(e_date,G$13,e_name,"?*")<=COUNTIFS(t_date,G$13,t_name,"?*",t_status,"<>❌ Отменена"),INDEX(t_label,MATCH(G$13&"#"&(2-COUNTIFS(e_date,G$13,e_name,"?*")),t_key,0)),"")),"") | H15: =IFERROR(IF(2<=COUNTIFS(e_date,H$13,e_name,"?*"),INDEX(e_label,MATCH(H$13&"#"&2,e_key,0)),IF(2-COUNTIFS(e_date,H$13,e_name,"?*")<=COUNTIFS(t_date,H$13,t_name,"?*",t_status,"<>❌ Отменена"),INDEX(t_label,MATCH(H$13&"#"&(2-COUNTIFS(e_date,H$13,e_name,"?*")),t_key,0)),"")),"")
B16: =IFERROR(IF(3<=COUNTIFS(e_date,B$13,e_name,"?*"),INDEX(e_label,MATCH(B$13&"#"&3,e_key,0)),IF(3-COUNTIFS(e_date,B$13,e_name,"?*")<=COUNTIFS(t_date,B$13,t_name,"?*",t_status,"<>❌ Отменена"),INDEX(t_label,MATCH(B$13&"#"&(3-COUNTIFS(e_date,B$13,e_name,"?*")),t_key,0)),"")),"") | C16: =IFERROR(IF(3<=COUNTIFS(e_date,C$13,e_name,"?*"),INDEX(e_label,MATCH(C$13&"#"&3,e_key,0)),IF(3-COUNTIFS(e_date,C$13,e_name,"?*")<=COUNTIFS(t_date,C$13,t_name,"?*",t_status,"<>❌ Отменена"),INDEX(t_label,MATCH(C$13&"#"&(3-COUNTIFS(e_date,C$13,e_name,"?*")),t_key,0)),"")),"") | D16: =IFERROR(IF(3<=COUNTIFS(e_date,D$13,e_name,"?*"),INDEX(e_label,MATCH(D$13&"#"&3,e_key,0)),IF(3-COUNTIFS(e_date,D$13,e_name,"?*")<=COUNTIFS(t_date,D$13,t_name,"?*",t_status,"<>❌ Отменена"),INDEX(t_label,MATCH(D$13&"#"&(3-COUNTIFS(e_date,D$13,e_name,"?*")),t_key,0)),"")),"") | E16: =IFERROR(IF(3<=COUNTIFS(e_date,E$13,e_name,"?*"),INDEX(e_label,MATCH(E$13&"#"&3,e_key,0)),IF(3-COUNTIFS(e_date,E$13,e_name,"?*")<=COUNTIFS(t_date,E$13,t_name,"?*",t_status,"<>❌ Отменена"),INDEX(t_label,MATCH(E$13&"#"&(3-COUNTIFS(e_date,E$13,e_name,"?*")),t_key,0)),"")),"") | F16: =IFERROR(IF(3<=COUNTIFS(e_date,F$13,e_name,"?*"),INDEX(e_label,MATCH(F$13&"#"&3,e_key,0)),IF(3-COUNTIFS(e_date,F$13,e_name,"?*")<=COUNTIFS(t_date,F$13,t_name,"?*",t_status,"<>❌ Отменена"),INDEX(t_label,MATCH(F$13&"#"&(3-COUNTIFS(e_date,F$13,e_name,"?*")),t_key,0)),"")),"") | G16: =IFERROR(IF(3<=COUNTIFS(e_date,G$13,e_name,"?*"),INDEX(e_label,MATCH(G$13&"#"&3,e_key,0)),IF(3-COUNTIFS(e_date,G$13,e_name,"?*")<=COUNTIFS(t_date,G$13,t_name,"?*",t_status,"<>❌ Отменена"),INDEX(t_label,MATCH(G$13&"#"&(3-COUNTIFS(e_date,G$13,e_name,"?*")),t_key,0)),"")),"") | H16: =IFERROR(IF(3<=COUNTIFS(e_date,H$13,e_name,"?*"),INDEX(e_label,MATCH(H$13&"#"&3,e_key,0)),IF(3-COUNTIFS(e_date,H$13,e_name,"?*")<=COUNTIFS(t_date,H$13,t_name,"?*",t_status,"<>❌ Отменена"),INDEX(t_label,MATCH(H$13&"#"&(3-COUNTIFS(e_date,H$13,e_name,"?*")),t_key,0)),"")),"") | J16: 🔎 Обозначения
B17: =IFERROR(IF(4<=COUNTIFS(e_date,B$13,e_name,"?*"),INDEX(e_label,MATCH(B$13&"#"&4,e_key,0)),IF(4-COUNTIFS(e_date,B$13,e_name,"?*")<=COUNTIFS(t_date,B$13,t_name,"?*",t_status,"<>❌ Отменена"),INDEX(t_label,MATCH(B$13&"#"&(4-COUNTIFS(e_date,B$13,e_name,"?*")),t_key,0)),"")),"") | C17: =IFERROR(IF(4<=COUNTIFS(e_date,C$13,e_name,"?*"),INDEX(e_label,MATCH(C$13&"#"&4,e_key,0)),IF(4-COUNTIFS(e_date,C$13,e_name,"?*")<=COUNTIFS(t_date,C$13,t_name,"?*",t_status,"<>❌ Отменена"),INDEX(t_label,MATCH(C$13&"#"&(4-COUNTIFS(e_date,C$13,e_name,"?*")),t_key,0)),"")),"") | D17: =IFERROR(IF(4<=COUNTIFS(e_date,D$13,e_name,"?*"),INDEX(e_label,MATCH(D$13&"#"&4,e_key,0)),IF(4-COUNTIFS(e_date,D$13,e_name,"?*")<=COUNTIFS(t_date,D$13,t_name,"?*",t_status,"<>❌ Отменена"),INDEX(t_label,MATCH(D$13&"#"&(4-COUNTIFS(e_date,D$13,e_name,"?*")),t_key,0)),"")),"") | E17: =IFERROR(IF(4<=COUNTIFS(e_date,E$13,e_name,"?*"),INDEX(e_label,MATCH(E$13&"#"&4,e_key,0)),IF(4-COUNTIFS(e_date,E$13,e_name,"?*")<=COUNTIFS(t_date,E$13,t_name,"?*",t_status,"<>❌ Отменена"),INDEX(t_label,MATCH(E$13&"#"&(4-COUNTIFS(e_date,E$13,e_name,"?*")),t_key,0)),"")),"") | F17: =IFERROR(IF(4<=COUNTIFS(e_date,F$13,e_name,"?*"),INDEX(e_label,MATCH(F$13&"#"&4,e_key,0)),IF(4-COUNTIFS(e_date,F$13,e_name,"?*")<=COUNTIFS(t_date,F$13,t_name,"?*",t_status,"<>❌ Отменена"),INDEX(t_label,MATCH(F$13&"#"&(4-COUNTIFS(e_date,F$13,e_name,"?*")),t_key,0)),"")),"") | G17: =IFERROR(IF(4<=COUNTIFS(e_date,G$13,e_name,"?*"),INDEX(e_label,MATCH(G$13&"#"&4,e_key,0)),IF(4-COUNTIFS(e_date,G$13,e_name,"?*")<=COUNTIFS(t_date,G$13,t_name,"?*",t_status,"<>❌ Отменена"),INDEX(t_label,MATCH(G$13&"#"&(4-COUNTIFS(e_date,G$13,e_name,"?*")),t_key,0)),"")),"") | H17: =IFERROR(IF(4<=COUNTIFS(e_date,H$13,e_name,"?*"),INDEX(e_label,MATCH(H$13&"#"&4,e_key,0)),IF(4-COUNTIFS(e_date,H$13,e_name,"?*")<=COUNTIFS(t_date,H$13,t_name,"?*",t_status,"<>❌ Отменена"),INDEX(t_label,MATCH(H$13&"#"&(4-COUNTIFS(e_date,H$13,e_name,"?*")),t_key,0)),"")),"") | J17: ⏰ 09:00–10:00 — дело из расписания
B18: =IFERROR(IF(5<=COUNTIFS(e_date,B$13,e_name,"?*"),INDEX(e_label,MATCH(B$13&"#"&5,e_key,0)),IF(5-COUNTIFS(e_date,B$13,e_name,"?*")<=COUNTIFS(t_date,B$13,t_name,"?*",t_status,"<>❌ Отменена"),INDEX(t_label,MATCH(B$13&"#"&(5-COUNTIFS(e_date,B$13,e_name,"?*")),t_key,0)),"")),"") | C18: =IFERROR(IF(5<=COUNTIFS(e_date,C$13,e_name,"?*"),INDEX(e_label,MATCH(C$13&"#"&5,e_key,0)),IF(5-COUNTIFS(e_date,C$13,e_name,"?*")<=COUNTIFS(t_date,C$13,t_name,"?*",t_status,"<>❌ Отменена"),INDEX(t_label,MATCH(C$13&"#"&(5-COUNTIFS(e_date,C$13,e_name,"?*")),t_key,0)),"")),"") | D18: =IFERROR(IF(5<=COUNTIFS(e_date,D$13,e_name,"?*"),INDEX(e_label,MATCH(D$13&"#"&5,e_key,0)),IF(5-COUNTIFS(e_date,D$13,e_name,"?*")<=COUNTIFS(t_date,D$13,t_name,"?*",t_status,"<>❌ Отменена"),INDEX(t_label,MATCH(D$13&"#"&(5-COUNTIFS(e_date,D$13,e_name,"?*")),t_key,0)),"")),"") | E18: =IFERROR(IF(5<=COUNTIFS(e_date,E$13,e_name,"?*"),INDEX(e_label,MATCH(E$13&"#"&5,e_key,0)),IF(5-COUNTIFS(e_date,E$13,e_name,"?*")<=COUNTIFS(t_date,E$13,t_name,"?*",t_status,"<>❌ Отменена"),INDEX(t_label,MATCH(E$13&"#"&(5-COUNTIFS(e_date,E$13,e_name,"?*")),t_key,0)),"")),"") | F18: =IFERROR(IF(5<=COUNTIFS(e_date,F$13,e_name,"?*"),INDEX(e_label,MATCH(F$13&"#"&5,e_key,0)),IF(5-COUNTIFS(e_date,F$13,e_name,"?*")<=COUNTIFS(t_date,F$13,t_name,"?*",t_status,"<>❌ Отменена"),INDEX(t_label,MATCH(F$13&"#"&(5-COUNTIFS(e_date,F$13,e_name,"?*")),t_key,0)),"")),"") | G18: =IFERROR(IF(5<=COUNTIFS(e_date,G$13,e_name,"?*"),INDEX(e_label,MATCH(G$13&"#"&5,e_key,0)),IF(5-COUNTIFS(e_date,G$13,e_name,"?*")<=COUNTIFS(t_date,G$13,t_name,"?*",t_status,"<>❌ Отменена"),INDEX(t_label,MATCH(G$13&"#"&(5-COUNTIFS(e_date,G$13,e_name,"?*")),t_key,0)),"")),"") | H18: =IFERROR(IF(5<=COUNTIFS(e_date,H$13,e_name,"?*"),INDEX(e_label,MATCH(H$13&"#"&5,e_key,0)),IF(5-COUNTIFS(e_date,H$13,e_name,"?*")<=COUNTIFS(t_date,H$13,t_name,"?*",t_status,"<>❌ Отменена"),INDEX(t_label,MATCH(H$13&"#"&(5-COUNTIFS(e_date,H$13,e_name,"?*")),t_key,0)),"")),"") | J18: ☐ задача в планах
B19: =IFERROR(IF(COUNTIFS(e_date,B$13,e_name,"?*")+COUNTIFS(t_date,B$13,t_name,"?*",t_status,"<>❌ Отменена")>6,"… ещё "&(COUNTIFS(e_date,B$13,e_name,"?*")+COUNTIFS(t_date,B$13,t_name,"?*",t_status,"<>❌ Отменена")-5),IF(6<=COUNTIFS(e_date,B$13,e_name,"?*"),INDEX(e_label,MATCH(B$13&"#"&6,e_key,0)),IF(6-COUNTIFS(e_date,B$13,e_name,"?*")<=COUNTIFS(t_date,B$13,t_name,"?*",t_status,"<>❌ Отменена"),INDEX(t_label,MATCH(B$13&"#"&(6-COUNTIFS(e_date,B$13,e_name,"?*")),t_key,0)),""))),"") | C19: =IFERROR(IF(COUNTIFS(e_date,C$13,e_name,"?*")+COUNTIFS(t_date,C$13,t_name,"?*",t_status,"<>❌ Отменена")>6,"… ещё "&(COUNTIFS(e_date,C$13,e_name,"?*")+COUNTIFS(t_date,C$13,t_name,"?*",t_status,"<>❌ Отменена")-5),IF(6<=COUNTIFS(e_date,C$13,e_name,"?*"),INDEX(e_label,MATCH(C$13&"#"&6,e_key,0)),IF(6-COUNTIFS(e_date,C$13,e_name,"?*")<=COUNTIFS(t_date,C$13,t_name,"?*",t_status,"<>❌ Отменена"),INDEX(t_label,MATCH(C$13&"#"&(6-COUNTIFS(e_date,C$13,e_name,"?*")),t_key,0)),""))),"") | D19: =IFERROR(IF(COUNTIFS(e_date,D$13,e_name,"?*")+COUNTIFS(t_date,D$13,t_name,"?*",t_status,"<>❌ Отменена")>6,"… ещё "&(COUNTIFS(e_date,D$13,e_name,"?*")+COUNTIFS(t_date,D$13,t_name,"?*",t_status,"<>❌ Отменена")-5),IF(6<=COUNTIFS(e_date,D$13,e_name,"?*"),INDEX(e_label,MATCH(D$13&"#"&6,e_key,0)),IF(6-COUNTIFS(e_date,D$13,e_name,"?*")<=COUNTIFS(t_date,D$13,t_name,"?*",t_status,"<>❌ Отменена"),INDEX(t_label,MATCH(D$13&"#"&(6-COUNTIFS(e_date,D$13,e_name,"?*")),t_key,0)),""))),"") | E19: =IFERROR(IF(COUNTIFS(e_date,E$13,e_name,"?*")+COUNTIFS(t_date,E$13,t_name,"?*",t_status,"<>❌ Отменена")>6,"… ещё "&(COUNTIFS(e_date,E$13,e_name,"?*")+COUNTIFS(t_date,E$13,t_name,"?*",t_status,"<>❌ Отменена")-5),IF(6<=COUNTIFS(e_date,E$13,e_name,"?*"),INDEX(e_label,MATCH(E$13&"#"&6,e_key,0)),IF(6-COUNTIFS(e_date,E$13,e_name,"?*")<=COUNTIFS(t_date,E$13,t_name,"?*",t_status,"<>❌ Отменена"),INDEX(t_label,MATCH(E$13&"#"&(6-COUNTIFS(e_date,E$13,e_name,"?*")),t_key,0)),""))),"") | F19: =IFERROR(IF(COUNTIFS(e_date,F$13,e_name,"?*")+COUNTIFS(t_date,F$13,t_name,"?*",t_status,"<>❌ Отменена")>6,"… ещё "&(COUNTIFS(e_date,F$13,e_name,"?*")+COUNTIFS(t_date,F$13,t_name,"?*",t_status,"<>❌ Отменена")-5),IF(6<=COUNTIFS(e_date,F$13,e_name,"?*"),INDEX(e_label,MATCH(F$13&"#"&6,e_key,0)),IF(6-COUNTIFS(e_date,F$13,e_name,"?*")<=COUNTIFS(t_date,F$13,t_name,"?*",t_status,"<>❌ Отменена"),INDEX(t_label,MATCH(F$13&"#"&(6-COUNTIFS(e_date,F$13,e_name,"?*")),t_key,0)),""))),"") | G19: =IFERROR(IF(COUNTIFS(e_date,G$13,e_name,"?*")+COUNTIFS(t_date,G$13,t_name,"?*",t_status,"<>❌ Отменена")>6,"… ещё "&(COUNTIFS(e_date,G$13,e_name,"?*")+COUNTIFS(t_date,G$13,t_name,"?*",t_status,"<>❌ Отменена")-5),IF(6<=COUNTIFS(e_date,G$13,e_name,"?*"),INDEX(e_label,MATCH(G$13&"#"&6,e_key,0)),IF(6-COUNTIFS(e_date,G$13,e_name,"?*")<=COUNTIFS(t_date,G$13,t_name,"?*",t_status,"<>❌ Отменена"),INDEX(t_label,MATCH(G$13&"#"&(6-COUNTIFS(e_date,G$13,e_name,"?*")),t_key,0)),""))),"") | H19: =IFERROR(IF(COUNTIFS(e_date,H$13,e_name,"?*")+COUNTIFS(t_date,H$13,t_name,"?*",t_status,"<>❌ Отменена")>6,"… ещё "&(COUNTIFS(e_date,H$13,e_name,"?*")+COUNTIFS(t_date,H$13,t_name,"?*",t_status,"<>❌ Отменена")-5),IF(6<=COUNTIFS(e_date,H$13,e_name,"?*"),INDEX(e_label,MATCH(H$13&"#"&6,e_key,0)),IF(6-COUNTIFS(e_date,H$13,e_name,"?*")<=COUNTIFS(t_date,H$13,t_name,"?*",t_status,"<>❌ Отменена"),INDEX(t_label,MATCH(H$13&"#"&(6-COUNTIFS(e_date,H$13,e_name,"?*")),t_key,0)),""))),"") | J19: ❗ задача просрочена
B20: =(DATE(cal_y,cal_m,1)-WEEKDAY(DATE(cal_y,cal_m,1),2)+1)+14 | C20: =(DATE(cal_y,cal_m,1)-WEEKDAY(DATE(cal_y,cal_m,1),2)+1)+15 | D20: =(DATE(cal_y,cal_m,1)-WEEKDAY(DATE(cal_y,cal_m,1),2)+1)+16 | E20: =(DATE(cal_y,cal_m,1)-WEEKDAY(DATE(cal_y,cal_m,1),2)+1)+17 | F20: =(DATE(cal_y,cal_m,1)-WEEKDAY(DATE(cal_y,cal_m,1),2)+1)+18 | G20: =(DATE(cal_y,cal_m,1)-WEEKDAY(DATE(cal_y,cal_m,1),2)+1)+19 | H20: =(DATE(cal_y,cal_m,1)-WEEKDAY(DATE(cal_y,cal_m,1),2)+1)+20 | J20: ✔ сделано (зачёркнуто)
B21: =IFERROR(IF(1<=COUNTIFS(e_date,B$20,e_name,"?*"),INDEX(e_label,MATCH(B$20&"#"&1,e_key,0)),IF(1-COUNTIFS(e_date,B$20,e_name,"?*")<=COUNTIFS(t_date,B$20,t_name,"?*",t_status,"<>❌ Отменена"),INDEX(t_label,MATCH(B$20&"#"&(1-COUNTIFS(e_date,B$20,e_name,"?*")),t_key,0)),"")),"") | C21: =IFERROR(IF(1<=COUNTIFS(e_date,C$20,e_name,"?*"),INDEX(e_label,MATCH(C$20&"#"&1,e_key,0)),IF(1-COUNTIFS(e_date,C$20,e_name,"?*")<=COUNTIFS(t_date,C$20,t_name,"?*",t_status,"<>❌ Отменена"),INDEX(t_label,MATCH(C$20&"#"&(1-COUNTIFS(e_date,C$20,e_name,"?*")),t_key,0)),"")),"") | D21: =IFERROR(IF(1<=COUNTIFS(e_date,D$20,e_name,"?*"),INDEX(e_label,MATCH(D$20&"#"&1,e_key,0)),IF(1-COUNTIFS(e_date,D$20,e_name,"?*")<=COUNTIFS(t_date,D$20,t_name,"?*",t_status,"<>❌ Отменена"),INDEX(t_label,MATCH(D$20&"#"&(1-COUNTIFS(e_date,D$20,e_name,"?*")),t_key,0)),"")),"") | E21: =IFERROR(IF(1<=COUNTIFS(e_date,E$20,e_name,"?*"),INDEX(e_label,MATCH(E$20&"#"&1,e_key,0)),IF(1-COUNTIFS(e_date,E$20,e_name,"?*")<=COUNTIFS(t_date,E$20,t_name,"?*",t_status,"<>❌ Отменена"),INDEX(t_label,MATCH(E$20&"#"&(1-COUNTIFS(e_date,E$20,e_name,"?*")),t_key,0)),"")),"") | F21: =IFERROR(IF(1<=COUNTIFS(e_date,F$20,e_name,"?*"),INDEX(e_label,MATCH(F$20&"#"&1,e_key,0)),IF(1-COUNTIFS(e_date,F$20,e_name,"?*")<=COUNTIFS(t_date,F$20,t_name,"?*",t_status,"<>❌ Отменена"),INDEX(t_label,MATCH(F$20&"#"&(1-COUNTIFS(e_date,F$20,e_name,"?*")),t_key,0)),"")),"") | G21: =IFERROR(IF(1<=COUNTIFS(e_date,G$20,e_name,"?*"),INDEX(e_label,MATCH(G$20&"#"&1,e_key,0)),IF(1-COUNTIFS(e_date,G$20,e_name,"?*")<=COUNTIFS(t_date,G$20,t_name,"?*",t_status,"<>❌ Отменена"),INDEX(t_label,MATCH(G$20&"#"&(1-COUNTIFS(e_date,G$20,e_name,"?*")),t_key,0)),"")),"") | H21: =IFERROR(IF(1<=COUNTIFS(e_date,H$20,e_name,"?*"),INDEX(e_label,MATCH(H$20&"#"&1,e_key,0)),IF(1-COUNTIFS(e_date,H$20,e_name,"?*")<=COUNTIFS(t_date,H$20,t_name,"?*",t_status,"<>❌ Отменена"),INDEX(t_label,MATCH(H$20&"#"&(1-COUNTIFS(e_date,H$20,e_name,"?*")),t_key,0)),"")),"") | J21: ✖ пропущено / отменено
B22: =IFERROR(IF(2<=COUNTIFS(e_date,B$20,e_name,"?*"),INDEX(e_label,MATCH(B$20&"#"&2,e_key,0)),IF(2-COUNTIFS(e_date,B$20,e_name,"?*")<=COUNTIFS(t_date,B$20,t_name,"?*",t_status,"<>❌ Отменена"),INDEX(t_label,MATCH(B$20&"#"&(2-COUNTIFS(e_date,B$20,e_name,"?*")),t_key,0)),"")),"") | C22: =IFERROR(IF(2<=COUNTIFS(e_date,C$20,e_name,"?*"),INDEX(e_label,MATCH(C$20&"#"&2,e_key,0)),IF(2-COUNTIFS(e_date,C$20,e_name,"?*")<=COUNTIFS(t_date,C$20,t_name,"?*",t_status,"<>❌ Отменена"),INDEX(t_label,MATCH(C$20&"#"&(2-COUNTIFS(e_date,C$20,e_name,"?*")),t_key,0)),"")),"") | D22: =IFERROR(IF(2<=COUNTIFS(e_date,D$20,e_name,"?*"),INDEX(e_label,MATCH(D$20&"#"&2,e_key,0)),IF(2-COUNTIFS(e_date,D$20,e_name,"?*")<=COUNTIFS(t_date,D$20,t_name,"?*",t_status,"<>❌ Отменена"),INDEX(t_label,MATCH(D$20&"#"&(2-COUNTIFS(e_date,D$20,e_name,"?*")),t_key,0)),"")),"") | E22: =IFERROR(IF(2<=COUNTIFS(e_date,E$20,e_name,"?*"),INDEX(e_label,MATCH(E$20&"#"&2,e_key,0)),IF(2-COUNTIFS(e_date,E$20,e_name,"?*")<=COUNTIFS(t_date,E$20,t_name,"?*",t_status,"<>❌ Отменена"),INDEX(t_label,MATCH(E$20&"#"&(2-COUNTIFS(e_date,E$20,e_name,"?*")),t_key,0)),"")),"") | F22: =IFERROR(IF(2<=COUNTIFS(e_date,F$20,e_name,"?*"),INDEX(e_label,MATCH(F$20&"#"&2,e_key,0)),IF(2-COUNTIFS(e_date,F$20,e_name,"?*")<=COUNTIFS(t_date,F$20,t_name,"?*",t_status,"<>❌ Отменена"),INDEX(t_label,MATCH(F$20&"#"&(2-COUNTIFS(e_date,F$20,e_name,"?*")),t_key,0)),"")),"") | G22: =IFERROR(IF(2<=COUNTIFS(e_date,G$20,e_name,"?*"),INDEX(e_label,MATCH(G$20&"#"&2,e_key,0)),IF(2-COUNTIFS(e_date,G$20,e_name,"?*")<=COUNTIFS(t_date,G$20,t_name,"?*",t_status,"<>❌ Отменена"),INDEX(t_label,MATCH(G$20&"#"&(2-COUNTIFS(e_date,G$20,e_name,"?*")),t_key,0)),"")),"") | H22: =IFERROR(IF(2<=COUNTIFS(e_date,H$20,e_name,"?*"),INDEX(e_label,MATCH(H$20&"#"&2,e_key,0)),IF(2-COUNTIFS(e_date,H$20,e_name,"?*")<=COUNTIFS(t_date,H$20,t_name,"?*",t_status,"<>❌ Отменена"),INDEX(t_label,MATCH(H$20&"#"&(2-COUNTIFS(e_date,H$20,e_name,"?*")),t_key,0)),"")),"") | J22: 🔥 высокий приоритет
B23: =IFERROR(IF(3<=COUNTIFS(e_date,B$20,e_name,"?*"),INDEX(e_label,MATCH(B$20&"#"&3,e_key,0)),IF(3-COUNTIFS(e_date,B$20,e_name,"?*")<=COUNTIFS(t_date,B$20,t_name,"?*",t_status,"<>❌ Отменена"),INDEX(t_label,MATCH(B$20&"#"&(3-COUNTIFS(e_date,B$20,e_name,"?*")),t_key,0)),"")),"") | C23: =IFERROR(IF(3<=COUNTIFS(e_date,C$20,e_name,"?*"),INDEX(e_label,MATCH(C$20&"#"&3,e_key,0)),IF(3-COUNTIFS(e_date,C$20,e_name,"?*")<=COUNTIFS(t_date,C$20,t_name,"?*",t_status,"<>❌ Отменена"),INDEX(t_label,MATCH(C$20&"#"&(3-COUNTIFS(e_date,C$20,e_name,"?*")),t_key,0)),"")),"") | D23: =IFERROR(IF(3<=COUNTIFS(e_date,D$20,e_name,"?*"),INDEX(e_label,MATCH(D$20&"#"&3,e_key,0)),IF(3-COUNTIFS(e_date,D$20,e_name,"?*")<=COUNTIFS(t_date,D$20,t_name,"?*",t_status,"<>❌ Отменена"),INDEX(t_label,MATCH(D$20&"#"&(3-COUNTIFS(e_date,D$20,e_name,"?*")),t_key,0)),"")),"") | E23: =IFERROR(IF(3<=COUNTIFS(e_date,E$20,e_name,"?*"),INDEX(e_label,MATCH(E$20&"#"&3,e_key,0)),IF(3-COUNTIFS(e_date,E$20,e_name,"?*")<=COUNTIFS(t_date,E$20,t_name,"?*",t_status,"<>❌ Отменена"),INDEX(t_label,MATCH(E$20&"#"&(3-COUNTIFS(e_date,E$20,e_name,"?*")),t_key,0)),"")),"") | F23: =IFERROR(IF(3<=COUNTIFS(e_date,F$20,e_name,"?*"),INDEX(e_label,MATCH(F$20&"#"&3,e_key,0)),IF(3-COUNTIFS(e_date,F$20,e_name,"?*")<=COUNTIFS(t_date,F$20,t_name,"?*",t_status,"<>❌ Отменена"),INDEX(t_label,MATCH(F$20&"#"&(3-COUNTIFS(e_date,F$20,e_name,"?*")),t_key,0)),"")),"") | G23: =IFERROR(IF(3<=COUNTIFS(e_date,G$20,e_name,"?*"),INDEX(e_label,MATCH(G$20&"#"&3,e_key,0)),IF(3-COUNTIFS(e_date,G$20,e_name,"?*")<=COUNTIFS(t_date,G$20,t_name,"?*",t_status,"<>❌ Отменена"),INDEX(t_label,MATCH(G$20&"#"&(3-COUNTIFS(e_date,G$20,e_name,"?*")),t_key,0)),"")),"") | H23: =IFERROR(IF(3<=COUNTIFS(e_date,H$20,e_name,"?*"),INDEX(e_label,MATCH(H$20&"#"&3,e_key,0)),IF(3-COUNTIFS(e_date,H$20,e_name,"?*")<=COUNTIFS(t_date,H$20,t_name,"?*",t_status,"<>❌ Отменена"),INDEX(t_label,MATCH(H$20&"#"&(3-COUNTIFS(e_date,H$20,e_name,"?*")),t_key,0)),"")),"") | J23: … ещё N — не поместилось
B24: =IFERROR(IF(4<=COUNTIFS(e_date,B$20,e_name,"?*"),INDEX(e_label,MATCH(B$20&"#"&4,e_key,0)),IF(4-COUNTIFS(e_date,B$20,e_name,"?*")<=COUNTIFS(t_date,B$20,t_name,"?*",t_status,"<>❌ Отменена"),INDEX(t_label,MATCH(B$20&"#"&(4-COUNTIFS(e_date,B$20,e_name,"?*")),t_key,0)),"")),"") | C24: =IFERROR(IF(4<=COUNTIFS(e_date,C$20,e_name,"?*"),INDEX(e_label,MATCH(C$20&"#"&4,e_key,0)),IF(4-COUNTIFS(e_date,C$20,e_name,"?*")<=COUNTIFS(t_date,C$20,t_name,"?*",t_status,"<>❌ Отменена"),INDEX(t_label,MATCH(C$20&"#"&(4-COUNTIFS(e_date,C$20,e_name,"?*")),t_key,0)),"")),"") | D24: =IFERROR(IF(4<=COUNTIFS(e_date,D$20,e_name,"?*"),INDEX(e_label,MATCH(D$20&"#"&4,e_key,0)),IF(4-COUNTIFS(e_date,D$20,e_name,"?*")<=COUNTIFS(t_date,D$20,t_name,"?*",t_status,"<>❌ Отменена"),INDEX(t_label,MATCH(D$20&"#"&(4-COUNTIFS(e_date,D$20,e_name,"?*")),t_key,0)),"")),"") | E24: =IFERROR(IF(4<=COUNTIFS(e_date,E$20,e_name,"?*"),INDEX(e_label,MATCH(E$20&"#"&4,e_key,0)),IF(4-COUNTIFS(e_date,E$20,e_name,"?*")<=COUNTIFS(t_date,E$20,t_name,"?*",t_status,"<>❌ Отменена"),INDEX(t_label,MATCH(E$20&"#"&(4-COUNTIFS(e_date,E$20,e_name,"?*")),t_key,0)),"")),"") | F24: =IFERROR(IF(4<=COUNTIFS(e_date,F$20,e_name,"?*"),INDEX(e_label,MATCH(F$20&"#"&4,e_key,0)),IF(4-COUNTIFS(e_date,F$20,e_name,"?*")<=COUNTIFS(t_date,F$20,t_name,"?*",t_status,"<>❌ Отменена"),INDEX(t_label,MATCH(F$20&"#"&(4-COUNTIFS(e_date,F$20,e_name,"?*")),t_key,0)),"")),"") | G24: =IFERROR(IF(4<=COUNTIFS(e_date,G$20,e_name,"?*"),INDEX(e_label,MATCH(G$20&"#"&4,e_key,0)),IF(4-COUNTIFS(e_date,G$20,e_name,"?*")<=COUNTIFS(t_date,G$20,t_name,"?*",t_status,"<>❌ Отменена"),INDEX(t_label,MATCH(G$20&"#"&(4-COUNTIFS(e_date,G$20,e_name,"?*")),t_key,0)),"")),"") | H24: =IFERROR(IF(4<=COUNTIFS(e_date,H$20,e_name,"?*"),INDEX(e_label,MATCH(H$20&"#"&4,e_key,0)),IF(4-COUNTIFS(e_date,H$20,e_name,"?*")<=COUNTIFS(t_date,H$20,t_name,"?*",t_status,"<>❌ Отменена"),INDEX(t_label,MATCH(H$20&"#"&(4-COUNTIFS(e_date,H$20,e_name,"?*")),t_key,0)),"")),"") | J24: Тёмный кружок — сегодня
B25: =IFERROR(IF(5<=COUNTIFS(e_date,B$20,e_name,"?*"),INDEX(e_label,MATCH(B$20&"#"&5,e_key,0)),IF(5-COUNTIFS(e_date,B$20,e_name,"?*")<=COUNTIFS(t_date,B$20,t_name,"?*",t_status,"<>❌ Отменена"),INDEX(t_label,MATCH(B$20&"#"&(5-COUNTIFS(e_date,B$20,e_name,"?*")),t_key,0)),"")),"") | C25: =IFERROR(IF(5<=COUNTIFS(e_date,C$20,e_name,"?*"),INDEX(e_label,MATCH(C$20&"#"&5,e_key,0)),IF(5-COUNTIFS(e_date,C$20,e_name,"?*")<=COUNTIFS(t_date,C$20,t_name,"?*",t_status,"<>❌ Отменена"),INDEX(t_label,MATCH(C$20&"#"&(5-COUNTIFS(e_date,C$20,e_name,"?*")),t_key,0)),"")),"") | D25: =IFERROR(IF(5<=COUNTIFS(e_date,D$20,e_name,"?*"),INDEX(e_label,MATCH(D$20&"#"&5,e_key,0)),IF(5-COUNTIFS(e_date,D$20,e_name,"?*")<=COUNTIFS(t_date,D$20,t_name,"?*",t_status,"<>❌ Отменена"),INDEX(t_label,MATCH(D$20&"#"&(5-COUNTIFS(e_date,D$20,e_name,"?*")),t_key,0)),"")),"") | E25: =IFERROR(IF(5<=COUNTIFS(e_date,E$20,e_name,"?*"),INDEX(e_label,MATCH(E$20&"#"&5,e_key,0)),IF(5-COUNTIFS(e_date,E$20,e_name,"?*")<=COUNTIFS(t_date,E$20,t_name,"?*",t_status,"<>❌ Отменена"),INDEX(t_label,MATCH(E$20&"#"&(5-COUNTIFS(e_date,E$20,e_name,"?*")),t_key,0)),"")),"") | F25: =IFERROR(IF(5<=COUNTIFS(e_date,F$20,e_name,"?*"),INDEX(e_label,MATCH(F$20&"#"&5,e_key,0)),IF(5-COUNTIFS(e_date,F$20,e_name,"?*")<=COUNTIFS(t_date,F$20,t_name,"?*",t_status,"<>❌ Отменена"),INDEX(t_label,MATCH(F$20&"#"&(5-COUNTIFS(e_date,F$20,e_name,"?*")),t_key,0)),"")),"") | G25: =IFERROR(IF(5<=COUNTIFS(e_date,G$20,e_name,"?*"),INDEX(e_label,MATCH(G$20&"#"&5,e_key,0)),IF(5-COUNTIFS(e_date,G$20,e_name,"?*")<=COUNTIFS(t_date,G$20,t_name,"?*",t_status,"<>❌ Отменена"),INDEX(t_label,MATCH(G$20&"#"&(5-COUNTIFS(e_date,G$20,e_name,"?*")),t_key,0)),"")),"") | H25: =IFERROR(IF(5<=COUNTIFS(e_date,H$20,e_name,"?*"),INDEX(e_label,MATCH(H$20&"#"&5,e_key,0)),IF(5-COUNTIFS(e_date,H$20,e_name,"?*")<=COUNTIFS(t_date,H$20,t_name,"?*",t_status,"<>❌ Отменена"),INDEX(t_label,MATCH(H$20&"#"&(5-COUNTIFS(e_date,H$20,e_name,"?*")),t_key,0)),"")),"")
B26: =IFERROR(IF(COUNTIFS(e_date,B$20,e_name,"?*")+COUNTIFS(t_date,B$20,t_name,"?*",t_status,"<>❌ Отменена")>6,"… ещё "&(COUNTIFS(e_date,B$20,e_name,"?*")+COUNTIFS(t_date,B$20,t_name,"?*",t_status,"<>❌ Отменена")-5),IF(6<=COUNTIFS(e_date,B$20,e_name,"?*"),INDEX(e_label,MATCH(B$20&"#"&6,e_key,0)),IF(6-COUNTIFS(e_date,B$20,e_name,"?*")<=COUNTIFS(t_date,B$20,t_name,"?*",t_status,"<>❌ Отменена"),INDEX(t_label,MATCH(B$20&"#"&(6-COUNTIFS(e_date,B$20,e_name,"?*")),t_key,0)),""))),"") | C26: =IFERROR(IF(COUNTIFS(e_date,C$20,e_name,"?*")+COUNTIFS(t_date,C$20,t_name,"?*",t_status,"<>❌ Отменена")>6,"… ещё "&(COUNTIFS(e_date,C$20,e_name,"?*")+COUNTIFS(t_date,C$20,t_name,"?*",t_status,"<>❌ Отменена")-5),IF(6<=COUNTIFS(e_date,C$20,e_name,"?*"),INDEX(e_label,MATCH(C$20&"#"&6,e_key,0)),IF(6-COUNTIFS(e_date,C$20,e_name,"?*")<=COUNTIFS(t_date,C$20,t_name,"?*",t_status,"<>❌ Отменена"),INDEX(t_label,MATCH(C$20&"#"&(6-COUNTIFS(e_date,C$20,e_name,"?*")),t_key,0)),""))),"") | D26: =IFERROR(IF(COUNTIFS(e_date,D$20,e_name,"?*")+COUNTIFS(t_date,D$20,t_name,"?*",t_status,"<>❌ Отменена")>6,"… ещё "&(COUNTIFS(e_date,D$20,e_name,"?*")+COUNTIFS(t_date,D$20,t_name,"?*",t_status,"<>❌ Отменена")-5),IF(6<=COUNTIFS(e_date,D$20,e_name,"?*"),INDEX(e_label,MATCH(D$20&"#"&6,e_key,0)),IF(6-COUNTIFS(e_date,D$20,e_name,"?*")<=COUNTIFS(t_date,D$20,t_name,"?*",t_status,"<>❌ Отменена"),INDEX(t_label,MATCH(D$20&"#"&(6-COUNTIFS(e_date,D$20,e_name,"?*")),t_key,0)),""))),"") | E26: =IFERROR(IF(COUNTIFS(e_date,E$20,e_name,"?*")+COUNTIFS(t_date,E$20,t_name,"?*",t_status,"<>❌ Отменена")>6,"… ещё "&(COUNTIFS(e_date,E$20,e_name,"?*")+COUNTIFS(t_date,E$20,t_name,"?*",t_status,"<>❌ Отменена")-5),IF(6<=COUNTIFS(e_date,E$20,e_name,"?*"),INDEX(e_label,MATCH(E$20&"#"&6,e_key,0)),IF(6-COUNTIFS(e_date,E$20,e_name,"?*")<=COUNTIFS(t_date,E$20,t_name,"?*",t_status,"<>❌ Отменена"),INDEX(t_label,MATCH(E$20&"#"&(6-COUNTIFS(e_date,E$20,e_name,"?*")),t_key,0)),""))),"") | F26: =IFERROR(IF(COUNTIFS(e_date,F$20,e_name,"?*")+COUNTIFS(t_date,F$20,t_name,"?*",t_status,"<>❌ Отменена")>6,"… ещё "&(COUNTIFS(e_date,F$20,e_name,"?*")+COUNTIFS(t_date,F$20,t_name,"?*",t_status,"<>❌ Отменена")-5),IF(6<=COUNTIFS(e_date,F$20,e_name,"?*"),INDEX(e_label,MATCH(F$20&"#"&6,e_key,0)),IF(6-COUNTIFS(e_date,F$20,e_name,"?*")<=COUNTIFS(t_date,F$20,t_name,"?*",t_status,"<>❌ Отменена"),INDEX(t_label,MATCH(F$20&"#"&(6-COUNTIFS(e_date,F$20,e_name,"?*")),t_key,0)),""))),"") | G26: =IFERROR(IF(COUNTIFS(e_date,G$20,e_name,"?*")+COUNTIFS(t_date,G$20,t_name,"?*",t_status,"<>❌ Отменена")>6,"… ещё "&(COUNTIFS(e_date,G$20,e_name,"?*")+COUNTIFS(t_date,G$20,t_name,"?*",t_status,"<>❌ Отменена")-5),IF(6<=COUNTIFS(e_date,G$20,e_name,"?*"),INDEX(e_label,MATCH(G$20&"#"&6,e_key,0)),IF(6-COUNTIFS(e_date,G$20,e_name,"?*")<=COUNTIFS(t_date,G$20,t_name,"?*",t_status,"<>❌ Отменена"),INDEX(t_label,MATCH(G$20&"#"&(6-COUNTIFS(e_date,G$20,e_name,"?*")),t_key,0)),""))),"") | H26: =IFERROR(IF(COUNTIFS(e_date,H$20,e_name,"?*")+COUNTIFS(t_date,H$20,t_name,"?*",t_status,"<>❌ Отменена")>6,"… ещё "&(COUNTIFS(e_date,H$20,e_name,"?*")+COUNTIFS(t_date,H$20,t_name,"?*",t_status,"<>❌ Отменена")-5),IF(6<=COUNTIFS(e_date,H$20,e_name,"?*"),INDEX(e_label,MATCH(H$20&"#"&6,e_key,0)),IF(6-COUNTIFS(e_date,H$20,e_name,"?*")<=COUNTIFS(t_date,H$20,t_name,"?*",t_status,"<>❌ Отменена"),INDEX(t_label,MATCH(H$20&"#"&(6-COUNTIFS(e_date,H$20,e_name,"?*")),t_key,0)),""))),"") | J26: Больше 6 записей в день? Полный список — в «🕘 План дня» (фильтр по дате).
B27: =(DATE(cal_y,cal_m,1)-WEEKDAY(DATE(cal_y,cal_m,1),2)+1)+21 | C27: =(DATE(cal_y,cal_m,1)-WEEKDAY(DATE(cal_y,cal_m,1),2)+1)+22 | D27: =(DATE(cal_y,cal_m,1)-WEEKDAY(DATE(cal_y,cal_m,1),2)+1)+23 | E27: =(DATE(cal_y,cal_m,1)-WEEKDAY(DATE(cal_y,cal_m,1),2)+1)+24 | F27: =(DATE(cal_y,cal_m,1)-WEEKDAY(DATE(cal_y,cal_m,1),2)+1)+25 | G27: =(DATE(cal_y,cal_m,1)-WEEKDAY(DATE(cal_y,cal_m,1),2)+1)+26 | H27: =(DATE(cal_y,cal_m,1)-WEEKDAY(DATE(cal_y,cal_m,1),2)+1)+27
B28: =IFERROR(IF(1<=COUNTIFS(e_date,B$27,e_name,"?*"),INDEX(e_label,MATCH(B$27&"#"&1,e_key,0)),IF(1-COUNTIFS(e_date,B$27,e_name,"?*")<=COUNTIFS(t_date,B$27,t_name,"?*",t_status,"<>❌ Отменена"),INDEX(t_label,MATCH(B$27&"#"&(1-COUNTIFS(e_date,B$27,e_name,"?*")),t_key,0)),"")),"") | C28: =IFERROR(IF(1<=COUNTIFS(e_date,C$27,e_name,"?*"),INDEX(e_label,MATCH(C$27&"#"&1,e_key,0)),IF(1-COUNTIFS(e_date,C$27,e_name,"?*")<=COUNTIFS(t_date,C$27,t_name,"?*",t_status,"<>❌ Отменена"),INDEX(t_label,MATCH(C$27&"#"&(1-COUNTIFS(e_date,C$27,e_name,"?*")),t_key,0)),"")),"") | D28: =IFERROR(IF(1<=COUNTIFS(e_date,D$27,e_name,"?*"),INDEX(e_label,MATCH(D$27&"#"&1,e_key,0)),IF(1-COUNTIFS(e_date,D$27,e_name,"?*")<=COUNTIFS(t_date,D$27,t_name,"?*",t_status,"<>❌ Отменена"),INDEX(t_label,MATCH(D$27&"#"&(1-COUNTIFS(e_date,D$27,e_name,"?*")),t_key,0)),"")),"") | E28: =IFERROR(IF(1<=COUNTIFS(e_date,E$27,e_name,"?*"),INDEX(e_label,MATCH(E$27&"#"&1,e_key,0)),IF(1-COUNTIFS(e_date,E$27,e_name,"?*")<=COUNTIFS(t_date,E$27,t_name,"?*",t_status,"<>❌ Отменена"),INDEX(t_label,MATCH(E$27&"#"&(1-COUNTIFS(e_date,E$27,e_name,"?*")),t_key,0)),"")),"") | F28: =IFERROR(IF(1<=COUNTIFS(e_date,F$27,e_name,"?*"),INDEX(e_label,MATCH(F$27&"#"&1,e_key,0)),IF(1-COUNTIFS(e_date,F$27,e_name,"?*")<=COUNTIFS(t_date,F$27,t_name,"?*",t_status,"<>❌ Отменена"),INDEX(t_label,MATCH(F$27&"#"&(1-COUNTIFS(e_date,F$27,e_name,"?*")),t_key,0)),"")),"") | G28: =IFERROR(IF(1<=COUNTIFS(e_date,G$27,e_name,"?*"),INDEX(e_label,MATCH(G$27&"#"&1,e_key,0)),IF(1-COUNTIFS(e_date,G$27,e_name,"?*")<=COUNTIFS(t_date,G$27,t_name,"?*",t_status,"<>❌ Отменена"),INDEX(t_label,MATCH(G$27&"#"&(1-COUNTIFS(e_date,G$27,e_name,"?*")),t_key,0)),"")),"") | H28: =IFERROR(IF(1<=COUNTIFS(e_date,H$27,e_name,"?*"),INDEX(e_label,MATCH(H$27&"#"&1,e_key,0)),IF(1-COUNTIFS(e_date,H$27,e_name,"?*")<=COUNTIFS(t_date,H$27,t_name,"?*",t_status,"<>❌ Отменена"),INDEX(t_label,MATCH(H$27&"#"&(1-COUNTIFS(e_date,H$27,e_name,"?*")),t_key,0)),"")),"")
B29: =IFERROR(IF(2<=COUNTIFS(e_date,B$27,e_name,"?*"),INDEX(e_label,MATCH(B$27&"#"&2,e_key,0)),IF(2-COUNTIFS(e_date,B$27,e_name,"?*")<=COUNTIFS(t_date,B$27,t_name,"?*",t_status,"<>❌ Отменена"),INDEX(t_label,MATCH(B$27&"#"&(2-COUNTIFS(e_date,B$27,e_name,"?*")),t_key,0)),"")),"") | C29: =IFERROR(IF(2<=COUNTIFS(e_date,C$27,e_name,"?*"),INDEX(e_label,MATCH(C$27&"#"&2,e_key,0)),IF(2-COUNTIFS(e_date,C$27,e_name,"?*")<=COUNTIFS(t_date,C$27,t_name,"?*",t_status,"<>❌ Отменена"),INDEX(t_label,MATCH(C$27&"#"&(2-COUNTIFS(e_date,C$27,e_name,"?*")),t_key,0)),"")),"") | D29: =IFERROR(IF(2<=COUNTIFS(e_date,D$27,e_name,"?*"),INDEX(e_label,MATCH(D$27&"#"&2,e_key,0)),IF(2-COUNTIFS(e_date,D$27,e_name,"?*")<=COUNTIFS(t_date,D$27,t_name,"?*",t_status,"<>❌ Отменена"),INDEX(t_label,MATCH(D$27&"#"&(2-COUNTIFS(e_date,D$27,e_name,"?*")),t_key,0)),"")),"") | E29: =IFERROR(IF(2<=COUNTIFS(e_date,E$27,e_name,"?*"),INDEX(e_label,MATCH(E$27&"#"&2,e_key,0)),IF(2-COUNTIFS(e_date,E$27,e_name,"?*")<=COUNTIFS(t_date,E$27,t_name,"?*",t_status,"<>❌ Отменена"),INDEX(t_label,MATCH(E$27&"#"&(2-COUNTIFS(e_date,E$27,e_name,"?*")),t_key,0)),"")),"") | F29: =IFERROR(IF(2<=COUNTIFS(e_date,F$27,e_name,"?*"),INDEX(e_label,MATCH(F$27&"#"&2,e_key,0)),IF(2-COUNTIFS(e_date,F$27,e_name,"?*")<=COUNTIFS(t_date,F$27,t_name,"?*",t_status,"<>❌ Отменена"),INDEX(t_label,MATCH(F$27&"#"&(2-COUNTIFS(e_date,F$27,e_name,"?*")),t_key,0)),"")),"") | G29: =IFERROR(IF(2<=COUNTIFS(e_date,G$27,e_name,"?*"),INDEX(e_label,MATCH(G$27&"#"&2,e_key,0)),IF(2-COUNTIFS(e_date,G$27,e_name,"?*")<=COUNTIFS(t_date,G$27,t_name,"?*",t_status,"<>❌ Отменена"),INDEX(t_label,MATCH(G$27&"#"&(2-COUNTIFS(e_date,G$27,e_name,"?*")),t_key,0)),"")),"") | H29: =IFERROR(IF(2<=COUNTIFS(e_date,H$27,e_name,"?*"),INDEX(e_label,MATCH(H$27&"#"&2,e_key,0)),IF(2-COUNTIFS(e_date,H$27,e_name,"?*")<=COUNTIFS(t_date,H$27,t_name,"?*",t_status,"<>❌ Отменена"),INDEX(t_label,MATCH(H$27&"#"&(2-COUNTIFS(e_date,H$27,e_name,"?*")),t_key,0)),"")),"")
B30: =IFERROR(IF(3<=COUNTIFS(e_date,B$27,e_name,"?*"),INDEX(e_label,MATCH(B$27&"#"&3,e_key,0)),IF(3-COUNTIFS(e_date,B$27,e_name,"?*")<=COUNTIFS(t_date,B$27,t_name,"?*",t_status,"<>❌ Отменена"),INDEX(t_label,MATCH(B$27&"#"&(3-COUNTIFS(e_date,B$27,e_name,"?*")),t_key,0)),"")),"") | C30: =IFERROR(IF(3<=COUNTIFS(e_date,C$27,e_name,"?*"),INDEX(e_label,MATCH(C$27&"#"&3,e_key,0)),IF(3-COUNTIFS(e_date,C$27,e_name,"?*")<=COUNTIFS(t_date,C$27,t_name,"?*",t_status,"<>❌ Отменена"),INDEX(t_label,MATCH(C$27&"#"&(3-COUNTIFS(e_date,C$27,e_name,"?*")),t_key,0)),"")),"") | D30: =IFERROR(IF(3<=COUNTIFS(e_date,D$27,e_name,"?*"),INDEX(e_label,MATCH(D$27&"#"&3,e_key,0)),IF(3-COUNTIFS(e_date,D$27,e_name,"?*")<=COUNTIFS(t_date,D$27,t_name,"?*",t_status,"<>❌ Отменена"),INDEX(t_label,MATCH(D$27&"#"&(3-COUNTIFS(e_date,D$27,e_name,"?*")),t_key,0)),"")),"") | E30: =IFERROR(IF(3<=COUNTIFS(e_date,E$27,e_name,"?*"),INDEX(e_label,MATCH(E$27&"#"&3,e_key,0)),IF(3-COUNTIFS(e_date,E$27,e_name,"?*")<=COUNTIFS(t_date,E$27,t_name,"?*",t_status,"<>❌ Отменена"),INDEX(t_label,MATCH(E$27&"#"&(3-COUNTIFS(e_date,E$27,e_name,"?*")),t_key,0)),"")),"") | F30: =IFERROR(IF(3<=COUNTIFS(e_date,F$27,e_name,"?*"),INDEX(e_label,MATCH(F$27&"#"&3,e_key,0)),IF(3-COUNTIFS(e_date,F$27,e_name,"?*")<=COUNTIFS(t_date,F$27,t_name,"?*",t_status,"<>❌ Отменена"),INDEX(t_label,MATCH(F$27&"#"&(3-COUNTIFS(e_date,F$27,e_name,"?*")),t_key,0)),"")),"") | G30: =IFERROR(IF(3<=COUNTIFS(e_date,G$27,e_name,"?*"),INDEX(e_label,MATCH(G$27&"#"&3,e_key,0)),IF(3-COUNTIFS(e_date,G$27,e_name,"?*")<=COUNTIFS(t_date,G$27,t_name,"?*",t_status,"<>❌ Отменена"),INDEX(t_label,MATCH(G$27&"#"&(3-COUNTIFS(e_date,G$27,e_name,"?*")),t_key,0)),"")),"") | H30: =IFERROR(IF(3<=COUNTIFS(e_date,H$27,e_name,"?*"),INDEX(e_label,MATCH(H$27&"#"&3,e_key,0)),IF(3-COUNTIFS(e_date,H$27,e_name,"?*")<=COUNTIFS(t_date,H$27,t_name,"?*",t_status,"<>❌ Отменена"),INDEX(t_label,MATCH(H$27&"#"&(3-COUNTIFS(e_date,H$27,e_name,"?*")),t_key,0)),"")),"")
B31: =IFERROR(IF(4<=COUNTIFS(e_date,B$27,e_name,"?*"),INDEX(e_label,MATCH(B$27&"#"&4,e_key,0)),IF(4-COUNTIFS(e_date,B$27,e_name,"?*")<=COUNTIFS(t_date,B$27,t_name,"?*",t_status,"<>❌ Отменена"),INDEX(t_label,MATCH(B$27&"#"&(4-COUNTIFS(e_date,B$27,e_name,"?*")),t_key,0)),"")),"") | C31: =IFERROR(IF(4<=COUNTIFS(e_date,C$27,e_name,"?*"),INDEX(e_label,MATCH(C$27&"#"&4,e_key,0)),IF(4-COUNTIFS(e_date,C$27,e_name,"?*")<=COUNTIFS(t_date,C$27,t_name,"?*",t_status,"<>❌ Отменена"),INDEX(t_label,MATCH(C$27&"#"&(4-COUNTIFS(e_date,C$27,e_name,"?*")),t_key,0)),"")),"") | D31: =IFERROR(IF(4<=COUNTIFS(e_date,D$27,e_name,"?*"),INDEX(e_label,MATCH(D$27&"#"&4,e_key,0)),IF(4-COUNTIFS(e_date,D$27,e_name,"?*")<=COUNTIFS(t_date,D$27,t_name,"?*",t_status,"<>❌ Отменена"),INDEX(t_label,MATCH(D$27&"#"&(4-COUNTIFS(e_date,D$27,e_name,"?*")),t_key,0)),"")),"") | E31: =IFERROR(IF(4<=COUNTIFS(e_date,E$27,e_name,"?*"),INDEX(e_label,MATCH(E$27&"#"&4,e_key,0)),IF(4-COUNTIFS(e_date,E$27,e_name,"?*")<=COUNTIFS(t_date,E$27,t_name,"?*",t_status,"<>❌ Отменена"),INDEX(t_label,MATCH(E$27&"#"&(4-COUNTIFS(e_date,E$27,e_name,"?*")),t_key,0)),"")),"") | F31: =IFERROR(IF(4<=COUNTIFS(e_date,F$27,e_name,"?*"),INDEX(e_label,MATCH(F$27&"#"&4,e_key,0)),IF(4-COUNTIFS(e_date,F$27,e_name,"?*")<=COUNTIFS(t_date,F$27,t_name,"?*",t_status,"<>❌ Отменена"),INDEX(t_label,MATCH(F$27&"#"&(4-COUNTIFS(e_date,F$27,e_name,"?*")),t_key,0)),"")),"") | G31: =IFERROR(IF(4<=COUNTIFS(e_date,G$27,e_name,"?*"),INDEX(e_label,MATCH(G$27&"#"&4,e_key,0)),IF(4-COUNTIFS(e_date,G$27,e_name,"?*")<=COUNTIFS(t_date,G$27,t_name,"?*",t_status,"<>❌ Отменена"),INDEX(t_label,MATCH(G$27&"#"&(4-COUNTIFS(e_date,G$27,e_name,"?*")),t_key,0)),"")),"") | H31: =IFERROR(IF(4<=COUNTIFS(e_date,H$27,e_name,"?*"),INDEX(e_label,MATCH(H$27&"#"&4,e_key,0)),IF(4-COUNTIFS(e_date,H$27,e_name,"?*")<=COUNTIFS(t_date,H$27,t_name,"?*",t_status,"<>❌ Отменена"),INDEX(t_label,MATCH(H$27&"#"&(4-COUNTIFS(e_date,H$27,e_name,"?*")),t_key,0)),"")),"")
